Workbook
Name Slicer_部門: #N/A
Name Slicer_部門1: #N/A
Name Slicer_部門2: #N/A
Name Slicer_部門3: #N/A
Name Slicer_部門4: #N/A
Name Slicer_等級2: #N/A
Name Slicer_等級21: #N/A
Name Slicer_等級22: #N/A
Name Slicer_等級23: #N/A
Name Slicer_等級24: #N/A

Sheet 等級分配表
A3: 計數 - 等級 | B3: 欄標籤
A4: 列標籤 | B4: B | C4: C | D4: D | E4: E | F4: 總計
A5: 加工組 | B5: 6 | C5: 9 | D5: 7 | E5: 8 | F5: 30
A6: 沖床組 | C6: 5 | D6: 1 | F6: 6
A7: 品保課 | B7: 1 | C7: 2 | D7: 1 | F7: 4
A8: 研發課 | B8: 2 | C8: 2 | E8: 1 | F8: 5
A9: 財務部 | B9: 2 | C9: 2 | E9: 1 | F9: 5
A10: 組一組 | B10: 1 | C10: 8 | D10: 3 | E10: 1 | F10: 13
A11: 組二組 | B11: 2 | C11: 3 | D11: 5 | E11: 3 | F11: 13
A12: 組三組 | B12: 3 | C12: 4 | D12: 1 | E12: 4 | F12: 12
A13: 塗裝組 | B13: 2 | C13: 8 | D13: 7 | E13: 3 | F13: 20
A14: 業務課 | B14: 1 | C14: 2 | F14: 3
A15: 資材課 | B15: 4 | C15: 7 | D15: 4 | F15: 15
A16: 製造課 | B16: 2 | C16: 1 | F16: 3
A17: 廠務部 | B17: 1 | C17: 1 | F17: 2
A18: 營業部 | C18: 1 | F18: 1
A19: 總務課 | C19: 2 | D19: 3 | E19: 1 | F19: 6
A20: 總經理室 | B20: 1 | F20: 1
A21: 總計 | B21: 28 | C21: 57 | D21: 32 | E21: 22 | F21: 139
D22: 超標 | F22: 超標
H24: A | I24: =145*5% -> 7.25
H25: B | I25: =145*20% -> 29 | K25: =I24+I25 -> 36.25
H26: C | I26: =145*40% -> 58
H27: D | I27: =145*30% -> 43.5
H28: E | I28: =145*5% -> 7.25

Sheet 名次排序
A1: 名次 | B1: 姓名 | C1: 部門 | D1: 晉升 | E1: 不 | G1: 名次 | H1: 姓名 | I1: 部門 | J1: 晉升 | K1: 包
A2: {=IFERROR( SMALL(員工資料!$I$2:$I$999, ROW(A1)), "")} | B2: {=IFERROR( INDEX(員工資料!$C$2:$C$999, SMALL( IF(員工資料!$I$2:$I$999=$A2, ROW(員工資料!$I$2:$I$999)-ROW(員工資料!$I$2)+1 ), COUNTIF($A$2:$A2,$A2) ) ), "")} | C2: {=IFERROR( INDEX(員工資料!$D$2:$D$999, SMALL( IF(員工資料!$I$2:$I$999=$A2, ROW(員工資料!$I$2:$I$999)-ROW(員工資料!$I$2)+1 ), COUNTIF($A$2:$A2,$A2) ) ), "")} | E2: 包 | G2: =IFERROR( SMALL(員工資料!$L$2:$L$999, ROW(G1)), "") | H2: {=IFERROR( INDEX(員工資料!$C$2:$C$999, SMALL( IF(員工資料!$L$2:$L$999=$G2, ROW(員工資料!$L$2:$L$999)-ROW(員工資料!$L$2)+1 ), COUNTIF($G$2:$G2,$G2) ) ), "")} | I2: {=IFERROR( INDEX(員工資料!$D$2:$D$999, SMALL( IF(員工資料!$L$2:$L$999=$G2, ROW(員工資料!$L$2:$L$999)-ROW(員工資料!$L$2)+1 ), COUNTIF($G$2:$G2,$G2) ) ), "")} | K2: 含
A3: {=IFERROR( SMALL(員工資料!$I$2:$I$999, ROW(A2)), "")} | B3: {=IFERROR( INDEX(員工資料!$C$2:$C$999, SMALL( IF(員工資料!$I$2:$I$999=$A3, ROW(員工資料!$I$2:$I$999)-ROW(員工資料!$I$2)+1 ), COUNTIF($A$2:$A3,$A3) ) ), "")} | C3: {=IFERROR( INDEX(員工資料!$D$2:$D$999, SMALL( IF(員工資料!$I$2:$I$999=$A3, ROW(員工資料!$I$2:$I$999)-ROW(員工資料!$I$2)+1 ), COUNTIF($A$2:$A3,$A3) ) ), "")} | E3: 含 | G3: =IFERROR( SMALL(員工資料!$L$2:$L$999, ROW(G2)), "") | H3: {=IFERROR( INDEX(員工資料!$C$2:$C$999, SMALL( IF(員工資料!$L$2:$L$999=$G3, ROW(員工資料!$L$2:$L$999)-ROW(員工資料!$L$2)+1 ), COUNTIF($G$2:$G3,$G3) ) ), "")} | I3: {=IFERROR( INDEX(員工資料!$D$2:$D$999, SMALL( IF(員工資料!$L$2:$L$999=$G3, ROW(員工資料!$L$2:$L$999)-ROW(員工資料!$L$2)+1 ), COUNTIF($G$2:$G3,$G3) ) ), "")} | K3: 獎
A4: {=IFERROR( SMALL(員工資料!$I$2:$I$999, ROW(A3)), "")} | B4: {=IFERROR( INDEX(員工資料!$C$2:$C$999, SMALL( IF(員工資料!$I$2:$I$999=$A4, ROW(員工資料!$I$2:$I$999)-ROW(員工資料!$I$2)+1 ), COUNTIF($A$2:$A4,$A4) ) ), "")} | C4: {=IFERROR( INDEX(員工資料!$D$2:$D$999, SMALL( IF(員工資料!$I$2:$I$999=$A4, ROW(員工資料!$I$2:$I$999)-ROW(員工資料!$I$2)+1 ), COUNTIF($A$2:$A4,$A4) ) ), "")} | E4: 獎 | G4: =IFERROR( SMALL(員工資料!$L$2:$L$999, ROW(G3)), "") | H4: {=IFERROR( INDEX(員工資料!$C$2:$C$999, SMALL( IF(員工資料!$L$2:$L$999=$G4, ROW(員工資料!$L$2:$L$999)-ROW(員工資料!$L$2)+1 ), COUNTIF($G$2:$G4,$G4) ) ), "")} | I4: {=IFERROR( INDEX(員工資料!$D$2:$D$999, SMALL( IF(員工資料!$L$2:$L$999=$G4, ROW(員工資料!$L$2:$L$999)-ROW(員工資料!$L$2)+1 ), COUNTIF($G$2:$G4,$G4) ) ), "")} | K4: 懲
A5: {=IFERROR( SMALL(員工資料!$I$2:$I$999, ROW(A4)), "")} | B5: {=IFERROR( INDEX(員工資料!$C$2:$C$999, SMALL( IF(員工資料!$I$2:$I$999=$A5, ROW(員工資料!$I$2:$I$999)-ROW(員工資料!$I$2)+1 ), COUNTIF($A$2:$A5,$A5) ) ), "")} | C5: {=IFERROR( INDEX(員工資料!$D$2:$D$999, SMALL( IF(員工資料!$I$2:$I$999=$A5, ROW(員工資料!$I$2:$I$999)-ROW(員工資料!$I$2)+1 ), COUNTIF($A$2:$A5,$A5) ) ), "")} | E5: 懲 | G5: =IFERROR( SMALL(員工資料!$L$2:$L$999, ROW(G4)), "") | H5: {=IFERROR( INDEX(員工資料!$C$2:$C$999, SMALL( IF(員工資料!$L$2:$L$999=$G5, ROW(員工資料!$L$2:$L$999)-ROW(員工資料!$L$2)+1 ), COUNTIF($G$2:$G5,$G5) ) ), "")} | I5: {=IFERROR( INDEX(員工資料!$D$2:$D$999, SMALL( IF(員工資料!$L$2:$L$999=$G5, ROW(員工資料!$L$2:$L$999)-ROW(員工資料!$L$2)+1 ), COUNTIF($G$2:$G5,$G5) ) ), "")} | K5: ←
A6: {=IFERROR( SMALL(員工資料!$I$2:$I$999, ROW(A5)), "")} | B6: {=IFERROR( INDEX(員工資料!$C$2:$C$999, SMALL( IF(員工資料!$I$2:$I$999=$A6, ROW(員工資料!$I$2:$I$999)-ROW(員工資料!$I$2)+1 ), COUNTIF($A$2:$A6,$A6) ) ), "")} | C6: {=IFERROR( INDEX(員工資料!$D$2:$D$999, SMALL( IF(員工資料!$I$2:$I$999=$A6, ROW(員工資料!$I$2:$I$999)-ROW(員工資料!$I$2)+1 ), COUNTIF($A$2:$A6,$A6) ) ), "")} | E6: ← | G6: =IFERROR( SMALL(員工資料!$L$2:$L$999, ROW(G5)), "") | H6: {=IFERROR( INDEX(員工資料!$C$2:$C$999, SMALL( IF(員工資料!$L$2:$L$999=$G6, ROW(員工資料!$L$2:$L$999)-ROW(員工資料!$L$2)+1 ), COUNTIF($G$2:$G6,$G6) ) ), "")} | I6: {=IFERROR( INDEX(員工資料!$D$2:$D$999, SMALL( IF(員工資料!$L$2:$L$999=$G6, ROW(員工資料!$L$2:$L$999)-ROW(員工資料!$L$2)+1 ), COUNTIF($G$2:$G6,$G6) ) ), "")}
A7: {=IFERROR( SMALL(員工資料!$I$2:$I$999, ROW(A6)), "")} | B7: {=IFERROR( INDEX(員工資料!$C$2:$C$999, SMALL( IF(員工資料!$I$2:$I$999=$A7, ROW(員工資料!$I$2:$I$999)-ROW(員工資料!$I$2)+1 ), COUNTIF($A$2:$A7,$A7) ) ), "")} | C7: {=IFERROR( INDEX(員工資料!$D$2:$D$999, SMALL( IF(員工資料!$I$2:$I$999=$A7, ROW(員工資料!$I$2:$I$999)-ROW(員工資料!$I$2)+1 ), COUNTIF($A$2:$A7,$A7) ) ), "")} | G7: =IFERROR( SMALL(員工資料!$L$2:$L$999, ROW(G6)), "") | H7: {=IFERROR( INDEX(員工資料!$C$2:$C$999, SMALL( IF(員工資料!$L$2:$L$999=$G7, ROW(員工資料!$L$2:$L$999)-ROW(員工資料!$L$2)+1 ), COUNTIF($G$2:$G7,$G7) ) ), "")} | I7: {=IFERROR( INDEX(員工資料!$D$2:$D$999, SMALL( IF(員工資料!$L$2:$L$999=$G7, ROW(員工資料!$L$2:$L$999)-ROW(員工資料!$L$2)+1 ), COUNTIF($G$2:$G7,$G7) ) ), "")}
A8: {=IFERROR( SMALL(員工資料!$I$2:$I$999, ROW(A7)), "")} | B8: {=IFERROR( INDEX(員工資料!$C$2:$C$999, SMALL( IF(員工資料!$I$2:$I$999=$A8, ROW(員工資料!$I$2:$I$999)-ROW(員工資料!$I$2)+1 ), COUNTIF($A$2:$A8,$A8) ) ), "")} | C8: {=IFERROR( INDEX(員工資料!$D$2:$D$999, SMALL( IF(員工資料!$I$2:$I$999=$A8, ROW(員工資料!$I$2:$I$999)-ROW(員工資料!$I$2)+1 ), COUNTIF($A$2:$A8,$A8) ) ), "")} | G8: =IFERROR( SMALL(員工資料!$L$2:$L$999, ROW(G7)), "") | H8: {=IFERROR( INDEX(員工資料!$C$2:$C$999, SMALL( IF(員工資料!$L$2:$L$999=$G8, ROW(員工資料!$L$2:$L$999)-ROW(員工資料!$L$2)+1 ), COUNTIF($G$2:$G8,$G8) ) ), "")} | I8: {=IFERROR( INDEX(員工資料!$D$2:$D$999, SMALL( IF(員工資料!$L$2:$L$999=$G8, ROW(員工資料!$L$2:$L$999)-ROW(員工資料!$L$2)+1 ), COUNTIF($G$2:$G8,$G8) ) ), "")}
A9: {=IFERROR( SMALL(員工資料!$I$2:$I$999, ROW(A8)), "")} | B9: {=IFERROR( INDEX(員工資料!$C$2:$C$999, SMALL( IF(員工資料!$I$2:$I$999=$A9, ROW(員工資料!$I$2:$I$999)-ROW(員工資料!$I$2)+1 ), COUNTIF($A$2:$A9,$A9) ) ), "")} | C9: {=IFERROR( INDEX(員工資料!$D$2:$D$999, SMALL( IF(員工資料!$I$2:$I$999=$A9, ROW(員工資料!$I$2:$I$999)-ROW(員工資料!$I$2)+1 ), COUNTIF($A$2:$A9,$A9) ) ), "")} | G9: =IFERROR( SMALL(員工資料!$L$2:$L$999, ROW(G8)), "") | H9: {=IFERROR( INDEX(員工資料!$C$2:$C$999, SMALL( IF(員工資料!$L$2:$L$999=$G9, ROW(員工資料!$L$2:$L$999)-ROW(員工資料!$L$2)+1 ), COUNTIF($G$2:$G9,$G9) ) ), "")} | I9: {=IFERROR( INDEX(員工資料!$D$2:$D$999, SMALL( IF(員工資料!$L$2:$L$999=$G9, ROW(員工資料!$L$2:$L$999)-ROW(員工資料!$L$2)+1 ), COUNTIF($G$2:$G9,$G9) ) ), "")}
A10: {=IFERROR( SMALL(員工資料!$I$2:$I$999, ROW(A9)), "")} | B10: {=IFERROR( INDEX(員工資料!$C$2:$C$999, SMALL( IF(員工資料!$I$2:$I$999=$A10, ROW(員工資料!$I$2:$I$999)-ROW(員工資料!$I$2)+1 ), COUNTIF($A$2:$A10,$A10) ) ), "")} | C10: {=IFERROR( INDEX(員工資料!$D$2:$D$999, SMALL( IF(員工資料!$I$2:$I$999=$A10, ROW(員工資料!$I$2:$I$999)-ROW(員工資料!$I$2)+1 ), COUNTIF($A$2:$A10,$A10) ) ), "")} | G10: =IFERROR( SMALL(員工資料!$L$2:$L$999, ROW(G9)), "") | H10: {=IFERROR( INDEX(員工資料!$C$2:$C$999, SMALL( IF(員工資料!$L$2:$L$999=$G10, ROW(員工資料!$L$2:$L$999)-ROW(員工資料!$L$2)+1 ), COUNTIF($G$2:$G10,$G10) ) ), "")} | I10: {=IFERROR( INDEX(員工資料!$D$2:$D$999, SMALL( IF(員工資料!$L$2:$L$999=$G10, ROW(員工資料!$L$2:$L$999)-ROW(員工資料!$L$2)+1 ), COUNTIF($G$2:$G10,$G10) ) ), "")}
A11: {=IFERROR( SMALL(員工資料!$I$2:$I$999, ROW(A10)), "")} | B11: {=IFERROR( INDEX(員工資料!$C$2:$C$999, SMALL( IF(員工資料!$I$2:$I$999=$A11, ROW(員工資料!$I$2:$I$999)-ROW(員工資料!$I$2)+1 ), COUNTIF($A$2:$A11,$A11) ) ), "")} | C11: {=IFERROR( INDEX(員工資料!$D$2:$D$999, SMALL( IF(員工資料!$I$2:$I$999=$A11, ROW(員工資料!$I$2:$I$999)-ROW(員工資料!$I$2)+1 ), COUNTIF($A$2:$A11,$A11) ) ), "")} | G11: =IFERROR( SMALL(員工資料!$L$2:$L$999, ROW(G10)), "") | H11: {=IFERROR( INDEX(員工資料!$C$2:$C$999, SMALL( IF(員工資料!$L$2:$L$999=$G11, ROW(員工資料!$L$2:$L$999)-ROW(員工資料!$L$2)+1 ), COUNTIF($G$2:$G11,$G11) ) ), "")} | I11: {=IFERROR( INDEX(員工資料!$D$2:$D$999, SMALL( IF(員工資料!$L$2:$L$999=$G11, ROW(員工資料!$L$2:$L$999)-ROW(員工資料!$L$2)+1 ), COUNTIF($G$2:$G11,$G11) ) ), "")}
A12: {=IFERROR( SMALL(員工資料!$I$2:$I$999, ROW(A11)), "")} | B12: {=IFERROR( INDEX(員工資料!$C$2:$C$999, SMALL( IF(員工資料!$I$2:$I$999=$A12, ROW(員工資料!$I$2:$I$999)-ROW(員工資料!$I$2)+1 ), COUNTIF($A$2:$A12,$A12) ) ), "")} | C12: {=IFERROR( INDEX(員工資料!$D$2:$D$999, SMALL( IF(員工資料!$I$2:$I$999=$A12, ROW(員工資料!$I$2:$I$999)-ROW(員工資料!$I$2)+1 ), COUNTIF($A$2:$A12,$A12) ) ), "")} | G12: =IFERROR( SMALL(員工資料!$L$2:$L$999, ROW(G11)), "") | H12: {=IFERROR( INDEX(員工資料!$C$2:$C$999, SMALL( IF(員工資料!$L$2:$L$999=$G12, ROW(員工資料!$L$2:$L$999)-ROW(員工資料!$L$2)+1 ), COUNTIF($G$2:$G12,$G12) ) ), "")} | I12: {=IFERROR( INDEX(員工資料!$D$2:$D$999, SMALL( IF(員工資料!$L$2:$L$999=$G12, ROW(員工資料!$L$2:$L$999)-ROW(員工資料!$L$2)+1 ), COUNTIF($G$2:$G12,$G12) ) ), "")}
A13: {=IFERROR( SMALL(員工資料!$I$2:$I$999, ROW(A12)), "")} | B13: {=IFERROR( INDEX(員工資料!$C$2:$C$999, SMALL( IF(員工資料!$I$2:$I$999=$A13, ROW(員工資料!$I$2:$I$999)-ROW(員工資料!$I$2)+1 ), COUNTIF($A$2:$A13,$A13) ) ), "")} | C13: {=IFERROR( INDEX(員工資料!$D$2:$D$999, SMALL( IF(員工資料!$I$2:$I$999=$A13, ROW(員工資料!$I$2:$I$999)-ROW(員工資料!$I$2)+1 ), COUNTIF($A$2:$A13,$A13) ) ), "")} | G13: =IFERROR( SMALL(員工資料!$L$2:$L$999, ROW(G12)), "") | H13: {=IFERROR( INDEX(員工資料!$C$2:$C$999, SMALL( IF(員工資料!$L$2:$L$999=$G13, ROW(員工資料!$L$2:$L$999)-ROW(員工資料!$L$2)+1 ), COUNTIF($G$2:$G13,$G13) ) ), "")} | I13: {=IFERROR( INDEX(員工資料!$D$2:$D$999, SMALL( IF(員工資料!$L$2:$L$999=$G13, ROW(員工資料!$L$2:$L$999)-ROW(員工資料!$L$2)+1 ), COUNTIF($G$2:$G13,$G13) ) ), "")}
A14: {=IFERROR( SMALL(員工資料!$I$2:$I$999, ROW(A13)), "")} | B14: {=IFERROR( INDEX(員工資料!$C$2:$C$999, SMALL( IF(員工資料!$I$2:$I$999=$A14, ROW(員工資料!$I$2:$I$999)-ROW(員工資料!$I$2)+1 ), COUNTIF($A$2:$A14,$A14) ) ), "")} | C14: {=IFERROR( INDEX(員工資料!$D$2:$D$999, SMALL( IF(員工資料!$I$2:$I$999=$A14, ROW(員工資料!$I$2:$I$999)-ROW(員工資料!$I$2)+1 ), COUNTIF($A$2:$A14,$A14) ) ), "")} | G14: =IFERROR( SMALL(員工資料!$L$2:$L$999, ROW(G13)), "") | H14: {=IFERROR( INDEX(員工資料!$C$2:$C$999, SMALL( IF(員工資料!$L$2:$L$999=$G14, ROW(員工資料!$L$2:$L$999)-ROW(員工資料!$L$2)+1 ), COUNTIF($G$2:$G14,$G14) ) ), "")} | I14: {=IFERROR( INDEX(員工資料!$D$2:$D$999, SMALL( IF(員工資料!$L$2:$L$999=$G14, ROW(員工資料!$L$2:$L$999)-ROW(員工資料!$L$2)+1 ), COUNTIF($G$2:$G14,$G14) ) ), "")}
A15: {=IFERROR( SMALL(員工資料!$I$2:$I$999, ROW(A14)), "")} | B15: {=IFERROR( INDEX(員工資料!$C$2:$C$999, SMALL( IF(員工資料!$I$2:$I$999=$A15, ROW(員工資料!$I$2:$I$999)-ROW(員工資料!$I$2)+1 ), COUNTIF($A$2:$A15,$A15) ) ), "")} | C15: {=IFERROR( INDEX(員工資料!$D$2:$D$999, SMALL( IF(員工資料!$I$2:$I$999=$A15, ROW(員工資料!$I$2:$I$999)-ROW(員工資料!$I$2)+1 ), COUNTIF($A$2:$A15,$A15) ) ), "")} | G15: =IFERROR( SMALL(員工資料!$L$2:$L$999, ROW(G14)), "") | H15: {=IFERROR( INDEX(員工資料!$C$2:$C$999, SMALL( IF(員工資料!$L$2:$L$999=$G15, ROW(員工資料!$L$2:$L$999)-ROW(員工資料!$L$2)+1 ), COUNTIF($G$2:$G15,$G15) ) ), "")} | I15: {=IFERROR( INDEX(員工資料!$D$2:$D$999, SMALL( IF(員工資料!$L$2:$L$999=$G15, ROW(員工資料!$L$2:$L$999)-ROW(員工資料!$L$2)+1 ), COUNTIF($G$2:$G15,$G15) ) ), "")}
A16: {=IFERROR( SMALL(員工資料!$I$2:$I$999, ROW(A15)), "")} | B16: {=IFERROR( INDEX(員工資料!$C$2:$C$999, SMALL( IF(員工資料!$I$2:$I$999=$A16, ROW(員工資料!$I$2:$I$999)-ROW(員工資料!$I$2)+1 ), COUNTIF($A$2:$A16,$A16) ) ), "")} | C16: {=IFERROR( INDEX(員工資料!$D$2:$D$999, SMALL( IF(員工資料!$I$2:$I$999=$A16, ROW(員工資料!$I$2:$I$999)-ROW(員工資料!$I$2)+1 ), COUNTIF($A$2:$A16,$A16) ) ), "")} | G16: =IFERROR( SMALL(員工資料!$L$2:$L$999, ROW(G15)), "") | H16: {=IFERROR( INDEX(員工資料!$C$2:$C$999, SMALL( IF(員工資料!$L$2:$L$999=$G16, ROW(員工資料!$L$2:$L$999)-ROW(員工資料!$L$2)+1 ), COUNTIF($G$2:$G16,$G16) ) ), "")} | I16: {=IFERROR( INDEX(員工資料!$D$2:$D$999, SMALL( IF(員工資料!$L$2:$L$999=$G16, ROW(員工資料!$L$2:$L$999)-ROW(員工資料!$L$2)+1 ), COUNTIF($G$2:$G16,$G16) ) ), "")}
A17: {=IFERROR( SMALL(員工資料!$I$2:$I$999, ROW(A16)), "")} | B17: {=IFERROR( INDEX(員工資料!$C$2:$C$999, SMALL( IF(員工資料!$I$2:$I$999=$A17, ROW(員工資料!$I$2:$I$999)-ROW(員工資料!$I$2)+1 ), COUNTIF($A$2:$A17,$A17) ) ), "")} | C17: {=IFERROR( INDEX(員工資料!$D$2:$D$999, SMALL( IF(員工資料!$I$2:$I$999=$A17, ROW(員工資料!$I$2:$I$999)-ROW(員工資料!$I$2)+1 ), COUNTIF($A$2:$A17,$A17) ) ), "")} | G17: =IFERROR( SMALL(員工資料!$L$2:$L$999, ROW(G16)), "") | H17: {=IFERROR( INDEX(員工資料!$C$2:$C$999, SMALL( IF(員工資料!$L$2:$L$999=$G17, ROW(員工資料!$L$2:$L$999)-ROW(員工資料!$L$2)+1 ), COUNTIF($G$2:$G17,$G17) ) ), "")} | I17: {=IFERROR( INDEX(員工資料!$D$2:$D$999, SMALL( IF(員工資料!$L$2:$L$999=$G17, ROW(員工資料!$L$2:$L$999)-ROW(員工資料!$L$2)+1 ), COUNTIF($G$2:$G17,$G17) ) ), "")}
A18: {=IFERROR( SMALL(員工資料!$I$2:$I$999, ROW(A17)), "")} | B18: {=IFERROR( INDEX(員工資料!$C$2:$C$999, SMALL( IF(員工資料!$I$2:$I$999=$A18, ROW(員工資料!$I$2:$I$999)-ROW(員工資料!$I$2)+1 ), COUNTIF($A$2:$A18,$A18) ) ), "")} | C18: {=IFERROR( INDEX(員工資料!$D$2:$D$999, SMALL( IF(員工資料!$I$2:$I$999=$A18, ROW(員工資料!$I$2:$I$999)-ROW(員工資料!$I$2)+1 ), COUNTIF($A$2:$A18,$A18) ) ), "")} | G18: =IFERROR( SMALL(員工資料!$L$2:$L$999, ROW(G17)), "") | H18: {=IFERROR( INDEX(員工資料!$C$2:$C$999, SMALL( IF(員工資料!$L$2:$L$999=$G18, ROW(員工資料!$L$2:$L$999)-ROW(員工資料!$L$2)+1 ), COUNTIF($G$2:$G18,$G18) ) ), "")} | I18: {=IFERROR( INDEX(員工資料!$D$2:$D$999, SMALL( IF(員工資料!$L$2:$L$999=$G18, ROW(員工資料!$L$2:$L$999)-ROW(員工資料!$L$2)+1 ), COUNTIF($G$2:$G18,$G18) ) ), "")}
... A136: {=IFERROR( SMALL(員工資料!$I$2:$I$999, ROW(A135)), "")} | B136: {=IFERROR( INDEX(員工資料!$C$2:$C$999, SMALL( IF(員工資料!$I$2:$I$999=$A136, ROW(員工資料!$I$2:$I$999)-ROW(員工資料!$I$2)+1 ), COUNTIF($A$2:$A136,$A136) ) ), "")} | C136: {=IFERROR( INDEX(員工資料!$D$2:$D$999, SMALL( IF(員工資料!$I$2:$I$999=$A136, ROW(員工資料!$I$2:$I$999)-ROW(員工資料!$I$2)+1 ), COUNTIF($A$2:$A136,$A136) ) ), "")} | G136: =IFERROR( SMALL(員工資料!$L$2:$L$999, ROW(G135)), "") | H136: {=IFERROR( INDEX(員工資料!$C$2:$C$999, SMALL( IF(員工資料!$L$2:$L$999=$G136, ROW(員工資料!$L$2:$L$999)-ROW(員工資料!$L$2)+1 ), COUNTIF($G$2:$G136,$G136) ) ), "")} | I136: {=IFERROR( INDEX(員工資料!$D$2:$D$999, SMALL( IF(員工資料!$L$2:$L$999=$G136, ROW(員工資料!$L$2:$L$999)-ROW(員工資料!$L$2)+1 ), COUNTIF($G$2:$G136,$G136) ) ), "")}
A137: {=IFERROR( SMALL(員工資料!$I$2:$I$999, ROW(A136)), "")} | B137: {=IFERROR( INDEX(員工資料!$C$2:$C$999, SMALL( IF(員工資料!$I$2:$I$999=$A137, ROW(員工資料!$I$2:$I$999)-ROW(員工資料!$I$2)+1 ), COUNTIF($A$2:$A137,$A137) ) ), "")} | C137: {=IFERROR( INDEX(員工資料!$D$2:$D$999, SMALL( IF(員工資料!$I$2:$I$999=$A137, ROW(員工資料!$I$2:$I$999)-ROW(員工資料!$I$2)+1 ), COUNTIF($A$2:$A137,$A137) ) ), "")} | G137: =IFERROR( SMALL(員工資料!$L$2:$L$999, ROW(G136)), "")
A138: {=IFERROR( SMALL(員工資料!$I$2:$I$999, ROW(A137)), "")} | B138: {=IFERROR( INDEX(員工資料!$C$2:$C$999, SMALL( IF(員工資料!$I$2:$I$999=$A138, ROW(員工資料!$I$2:$I$999)-ROW(員工資料!$I$2)+1 ), COUNTIF($A$2:$A138,$A138) ) ), "")} | C138: {=IFERROR( INDEX(員工資料!$D$2:$D$999, SMALL( IF(員工資料!$I$2:$I$999=$A138, ROW(員工資料!$I$2:$I$999)-ROW(員工資料!$I$2)+1 ), COUNTIF($A$2:$A138,$A138) ) ), "")} | G138: =IFERROR( SMALL(員工資料!$L$2:$L$999, ROW(G137)), "")
A139: {=IFERROR( SMALL(員工資料!$I$2:$I$999, ROW(A138)), "")} | B139: {=IFERROR( INDEX(員工資料!$C$2:$C$999, SMALL( IF(員工資料!$I$2:$I$999=$A139, ROW(員工資料!$I$2:$I$999)-ROW(員工資料!$I$2)+1 ), COUNTIF($A$2:$A139,$A139) ) ), "")} | C139: {=IFERROR( INDEX(員工資料!$D$2:$D$999, SMALL( IF(員工資料!$I$2:$I$999=$A139, ROW(員工資料!$I$2:$I$999)-ROW(員工資料!$I$2)+1 ), COUNTIF($A$2:$A139,$A139) ) ), "")} | G139: =IFERROR( SMALL(員工資料!$L$2:$L$999, ROW(G138)), "")
A140: {=IFERROR( SMALL(員工資料!$I$2:$I$999, ROW(A139)), "")} | B140: {=IFERROR( INDEX(員工資料!$C$2:$C$999, SMALL( IF(員工資料!$I$2:$I$999=$A140, ROW(員工資料!$I$2:$I$999)-ROW(員工資料!$I$2)+1 ), COUNTIF($A$2:$A140,$A140) ) ), "")} | C140: {=IFERROR( INDEX(員工資料!$D$2:$D$999, SMALL( IF(員工資料!$I$2:$I$999=$A140, ROW(員工資料!$I$2:$I$999)-ROW(員工資料!$I$2)+1 ), COUNTIF($A$2:$A140,$A140) ) ), "")} | G140: =IFERROR( SMALL(員工資料!$L$2:$L$999, ROW(G139)), "")
A141: {=IFERROR( SMALL(員工資料!$I$2:$I$999, ROW(A140)), "")} | B141: {=IFERROR( INDEX(員工資料!$C$2:$C$999, SMALL( IF(員工資料!$I$2:$I$999=$A141, ROW(員工資料!$I$2:$I$999)-ROW(員工資料!$I$2)+1 ), COUNTIF($A$2:$A141,$A141) ) ), "")} | C141: {=IFERROR( INDEX(員工資料!$D$2:$D$999, SMALL( IF(員工資料!$I$2:$I$999=$A141, ROW(員工資料!$I$2:$I$999)-ROW(員工資料!$I$2)+1 ), COUNTIF($A$2:$A141,$A141) ) ), "")} | G141: =IFERROR( SMALL(員工資料!$L$2:$L$999, ROW(G140)), "")
A142: {=IFERROR( SMALL(員工資料!$I$2:$I$999, ROW(A141)), "")} | B142: {=IFERROR( INDEX(員工資料!$C$2:$C$999, SMALL( IF(員工資料!$I$2:$I$999=$A142, ROW(員工資料!$I$2:$I$999)-ROW(員工資料!$I$2)+1 ), COUNTIF($A$2:$A142,$A142) ) ), "")} | C142: {=IFERROR( INDEX(員工資料!$D$2:$D$999, SMALL( IF(員工資料!$I$2:$I$999=$A142, ROW(員工資料!$I$2:$I$999)-ROW(員工資料!$I$2)+1 ), COUNTIF($A$2:$A142,$A142) ) ), "")} | G142: =IFERROR( SMALL(員工資料!$L$2:$L$999, ROW(G141)), "")
A143: {=IFERROR( SMALL(員工資料!$I$2:$I$999, ROW(A142)), "")} | B143: {=IFERROR( INDEX(員工資料!$C$2:$C$999, SMALL( IF(員工資料!$I$2:$I$999=$A143, ROW(員工資料!$I$2:$I$999)-ROW(員工資料!$I$2)+1 ), COUNTIF($A$2:$A143,$A143) ) ), "")} | C143: {=IFERROR( INDEX(員工資料!$D$2:$D$999, SMALL( IF(員工資料!$I$2:$I$999=$A143, ROW(員工資料!$I$2:$I$999)-ROW(員工資料!$I$2)+1 ), COUNTIF($A$2:$A143,$A143) ) ), "")} | G143: =IFERROR( SMALL(員工資料!$L$2:$L$999, ROW(G142)), "")
A144: {=IFERROR( SMALL(員工資料!$I$2:$I$999, ROW(A143)), "")} | B144: {=IFERROR( INDEX(員工資料!$C$2:$C$999, SMALL( IF(員工資料!$I$2:$I$999=$A144, ROW(員工資料!$I$2:$I$999)-ROW(員工資料!$I$2)+1 ), COUNTIF($A$2:$A144,$A144) ) ), "")} | C144: {=IFERROR( INDEX(員工資料!$D$2:$D$999, SMALL( IF(員工資料!$I$2:$I$999=$A144, ROW(員工資料!$I$2:$I$999)-ROW(員工資料!$I$2)+1 ), COUNTIF($A$2:$A144,$A144) ) ), "")} | G144: =IFERROR( SMALL(員工資料!$L$2:$L$999, ROW(G143)), "")
A145: {=IFERROR( SMALL(員工資料!$I$2:$I$999, ROW(A144)), "")} | B145: {=IFERROR( INDEX(員工資料!$C$2:$C$999, SMALL( IF(員工資料!$I$2:$I$999=$A145, ROW(員工資料!$I$2:$I$999)-ROW(員工資料!$I$2)+1 ), COUNTIF($A$2:$A145,$A145) ) ), "")} | C145: {=IFERROR( INDEX(員工資料!$D$2:$D$999, SMALL( IF(員工資料!$I$2:$I$999=$A145, ROW(員工資料!$I$2:$I$999)-ROW(員工資料!$I$2)+1 ), COUNTIF($A$2:$A145,$A145) ) ), "")} | G145: =IFERROR( SMALL(員工資料!$L$2:$L$999, ROW(G144)), "")
A146: {=IFERROR( SMALL(員工資料!$I$2:$I$999, ROW(A145)), "")} | B146: {=IFERROR( INDEX(員工資料!$C$2:$C$999, SMALL( IF(員工資料!$I$2:$I$999=$A146, ROW(員工資料!$I$2:$I$999)-ROW(員工資料!$I$2)+1 ), COUNTIF($A$2:$A146,$A146) ) ), "")} | C146: {=IFERROR( INDEX(員工資料!$D$2:$D$999, SMALL( IF(員工資料!$I$2:$I$999=$A146, ROW(員工資料!$I$2:$I$999)-ROW(員工資料!$I$2)+1 ), COUNTIF($A$2:$A146,$A146) ) ), "")} | G146: =IFERROR( SMALL(員工資料!$L$2:$L$999, ROW(G145)), "")

Sheet 包含獎懲等級分配
A3: 計數 - 等級2 | B3: 欄標籤
A4: 列標籤 | B4: A | C4: B | D4: C | E4: D | F4: E | G4: (空白) | H4: 總計
A5: 加工組 | C5: 6 | D5: 9 | E5: 7 | F5: 2 | H5: 24
A6: 沖床組 | D6: 5 | E6: 1 | H6: 6
A7: 品保課 | C7: 1 | D7: 2 | E7: 1 | H7: 4
A8: 研發課 | C8: 2 | D8: 2 | H8: 4
A9: 財務部 | C9: 2 | D9: 2 | H9: 4
A10: 組一組 | C10: 1 | D10: 8 | E10: 3 | F10: 1 | H10: 13
A11: 組二組 | C11: 2 | D11: 3 | E11: 4 | H11: 9
A12: 組三組 | C12: 3 | D12: 4 | E12: 1 | F12: 3 | H12: 11
A13: 塗裝組 | C13: 2 | D13: 8 | E13: 7 | F13: 3 | H13: 20
A14: 業務課 | C14: 1 | D14: 2 | H14: 3
A15: 董事會
A16: 資材課 | C16: 4 | D16: 5 | E16: 6 | H16: 15
A17: 製造課 | C17: 2 | D17: 1 | H17: 3
A18: 廠務部 | C18: 1 | D18: 1 | H18: 2
A19: 營業部 | D19: 1 | H19: 1
A20: 總務課 | D20: 2 | E20: 3 | H20: 5
A21: 總經理室 | B21: 1 | H21: 1
A22: (空白)
A23: 總計 | B23: 1 | C23: 27 | D23: 55 | E23: 33 | F23: 9 | H23: 125

Sheet 員工資料
A1: 是否建立 | B1: 工號 | C1: 姓名 | D1: 部門 | E1: 職位 | F1: 直接主管 | G1: 不包含獎懲總分 | H1: 等級 | I1: 全公司排名 | J1: 加權後總分 | K1: 等級2 | L1: 全公司排名2 | M1: 部內分數/初評 | N1: 跨部門分數 | O1: 主管複評 | P1: 嘉獎 | Q1: 小功 | R1: 大功 | S1: 申誡 | T1: 小過 | U1: 大過 | V1: 獎懲分數 | W1: 加權後總分
C2: 鄭淑鐘 | D2: 業務課 | E2: 助理專員 | F2: 伍珈彣 | G2: =表格1[[#This Row],[加權後總分]]-表格1[[#This Row],[獎懲分數]] -> #DIV/0! | H2: =IF(表格1[[#This Row],[不包含獎懲總分]]>=90,"A", IF(表格1[[#This Row],[不包含獎懲總分]]>=80,"B", IF(表格1[[#This Row],[不包含獎懲總分]]>=70,"C", IF(表格1[[#This Row],[不包含獎懲總分]]>=60,"D","E")))) -> #DIV/0! | I2: =_xlfn.RANK.EQ(G2,$G$2:$G$146,0) -> #DIV/0! | J2: =IF( AND(M2<>"",N2<>"",O2<>""), M2*20% + N2*50% + O2*30%, IF( AND(M2<>"",N2="",O2=""), M2, IF( AND(M2="",N2<>"",O2=""), N2, IF( AND(M2="",N2="",O2<>""), O2, IF( AND(M2<>"",N2<>"",O2=""), M2/(20%+50%)*20% + N2/(20%+50%)*50%, IF( AND(M2<>"",N2="",O2<>""), M2/(20%+30%)*20% + O2/(20%+30%)*30%, IF( AND(M2="",N2<>"",O2<>""), N2/(50%+30%)*50% + O2/(50%+30%)*30%, "" ) ) ) ) ) ) ) -> #DIV/0! | K2: =IF(J2>=90,"A", IF(J2>=77,"B", IF(J2>=70,"C", IF(J2>=60,"D","E")))) -> #DIV/0! | L2: =_xlfn.RANK.EQ(J2,$J$2:$J$146,0) -> #DIV/0! | M2: =表格1_3[[#This Row],[部內平均]] -> #DIV/0! | N2: =表格1_3[[#This Row],[共評平均]] -> #DIV/0! | O2: =表格1_3[[#This Row],[複評平均]] -> #DIV/0! | W2: #DIV/0!
B3: 2856 | C3: 陳玉慧 | D3: 業務課 | E3: 業務助理 | F3: 伍珈彣 | G3: =表格1[[#This Row],[加權後總分]]-表格1[[#This Row],[獎懲分數]] -> #DIV/0! | H3: =IF(表格1[[#This Row],[不包含獎懲總分]]>=90,"A", IF(表格1[[#This Row],[不包含獎懲總分]]>=80,"B", IF(表格1[[#This Row],[不包含獎懲總分]]>=70,"C", IF(表格1[[#This Row],[不包含獎懲總分]]>=60,"D","E")))) -> #DIV/0! | I3: =_xlfn.RANK.EQ(G3,$G$2:$G$146,0) -> #DIV/0! | J3: =IF( AND(M3<>"",N3<>"",O3<>""), M3*20% + N3*50% + O3*30%, IF( AND(M3<>"",N3="",O3=""), M3, IF( AND(M3="",N3<>"",O3=""), N3, IF( AND(M3="",N3="",O3<>""), O3, IF( AND(M3<>"",N3<>"",O3=""), M3/(20%+50%)*20% + N3/(20%+50%)*50%, IF( AND(M3<>"",N3="",O3<>""), M3/(20%+30%)*20% + O3/(20%+30%)*30%, IF( AND(M3="",N3<>"",O3<>""), N3/(50%+30%)*50% + O3/(50%+30%)*30%, "" ) ) ) ) ) ) + V3 ) -> #DIV/0! | K3: =IF(J3>=90,"A", IF(J3>=77,"B", IF(J3>=70,"C", IF(J3>=60,"D","E")))) -> #DIV/0! | L3: =_xlfn.RANK.EQ(J3,$J$2:$J$146,0) -> #DIV/0! | M3: =表格1_3[[#This Row],[部內平均]] -> #DIV/0! | N3: =表格1_3[[#This Row],[共評平均]] -> #DIV/0! | O3: =表格1_3[[#This Row],[複評平均]] -> #DIV/0! | W3: 109.61905 | X3: 1
B4: 2223 | C4: 伍珈彣 | D4: 業務課 | E4: 組長 | F4: 鄭景文 | G4: =表格1[[#This Row],[加權後總分]]-表格1[[#This Row],[獎懲分數]] -> #DIV/0! | H4: =IF(表格1[[#This Row],[不包含獎懲總分]]>=90,"A", IF(表格1[[#This Row],[不包含獎懲總分]]>=80,"B", IF(表格1[[#This Row],[不包含獎懲總分]]>=70,"C", IF(表格1[[#This Row],[不包含獎懲總分]]>=60,"D","E")))) -> #DIV/0! | I4: =_xlfn.RANK.EQ(G4,$G$2:$G$146,0) -> #DIV/0! | J4: =IF( AND(M4<>"",N4<>"",O4<>""), M4*20% + N4*50% + O4*30%, IF( AND(M4<>"",N4="",O4=""), M4, IF( AND(M4="",N4<>"",O4=""), N4, IF( AND(M4="",N4="",O4<>""), O4, IF( AND(M4<>"",N4<>"",O4=""), M4/(20%+50%)*20% + N4/(20%+50%)*50%, IF( AND(M4<>"",N4="",O4<>""), M4/(20%+30%)*20% + O4/(20%+30%)*30%, IF( AND(M4="",N4<>"",O4<>""), N4/(50%+30%)*50% + O4/(50%+30%)*30%, "" ) ) ) ) ) ) + V4 ) -> #DIV/0! | K4: =IF(J4>=90,"A", IF(J4>=77,"B", IF(J4>=70,"C", IF(J4>=60,"D","E")))) -> #DIV/0! | L4: =_xlfn.RANK.EQ(J4,$J$2:$J$146,0) -> #DIV/0! | M4: =表格1_3[[#This Row],[部內平均]] -> #DIV/0! | N4: =表格1_3[[#This Row],[共評平均]] -> #DIV/0! | W4: 87.6 | X4: 2
B5: 1115 | C5: 賴慶燁 | D5: 塗裝組 | E5: 助理工程師 | F5: 郭惠燕 | G5: =表格1[[#This Row],[加權後總分]]-表格1[[#This Row],[獎懲分數]] -> #DIV/0! | H5: =IF(表格1[[#This Row],[不包含獎懲總分]]>=90,"A", IF(表格1[[#This Row],[不包含獎懲總分]]>=80,"B", IF(表格1[[#This Row],[不包含獎懲總分]]>=70,"C", IF(表格1[[#This Row],[不包含獎懲總分]]>=60,"D","E")))) -> #DIV/0! | I5: =_xlfn.RANK.EQ(G5,$G$2:$G$146,0) -> #DIV/0! | J5: =IF( AND(M5<>"",N5<>"",O5<>""), M5*20% + N5*50% + O5*30%, IF( AND(M5<>"",N5="",O5=""), M5, IF( AND(M5="",N5<>"",O5=""), N5, IF( AND(M5="",N5="",O5<>""), O5, IF( AND(M5<>"",N5<>"",O5=""), M5/(20%+50%)*20% + N5/(20%+50%)*50%, IF( AND(M5<>"",N5="",O5<>""), M5/(20%+30%)*20% + O5/(20%+30%)*30%, IF( AND(M5="",N5<>"",O5<>""), N5/(50%+30%)*50% + O5/(50%+30%)*30%, "" ) ) ) ) ) ) + V5 ) -> #DIV/0! | K5: =IF(J5>=90,"A", IF(J5>=77,"B", IF(J5>=70,"C", IF(J5>=60,"D","E")))) -> #DIV/0! | L5: =_xlfn.RANK.EQ(J5,$J$2:$J$146,0) -> #DIV/0! | M5: =表格1_3[[#This Row],[部內平均]] -> #DIV/0! | O5: =表格1_3[[#This Row],[複評平均]] -> #DIV/0! | W5: 87.2 | X5: 3
A6: 移工 | B6: 3024 | C6: 那彭 | D6: 塗裝組 | E6: 技術員 | F6: 郭惠燕 | G6: =表格1[[#This Row],[加權後總分]]-表格1[[#This Row],[獎懲分數]] -> #DIV/0! | H6: =IF(表格1[[#This Row],[不包含獎懲總分]]>=90,"A", IF(表格1[[#This Row],[不包含獎懲總分]]>=80,"B", IF(表格1[[#This Row],[不包含獎懲總分]]>=70,"C", IF(表格1[[#This Row],[不包含獎懲總分]]>=60,"D","E")))) -> #DIV/0! | I6: =_xlfn.RANK.EQ(G6,$G$2:$G$146,0) -> #DIV/0! | J6: =IF( AND(M6<>"",N6<>"",O6<>""), M6*20% + N6*50% + O6*30%, IF( AND(M6<>"",N6="",O6=""), M6, IF( AND(M6="",N6<>"",O6=""), N6, IF( AND(M6="",N6="",O6<>""), O6, IF( AND(M6<>"",N6<>"",O6=""), M6/(20%+50%)*20% + N6/(20%+50%)*50%, IF( AND(M6<>"",N6="",O6<>""), M6/(20%+30%)*20% + O6/(20%+30%)*30%, IF( AND(M6="",N6<>"",O6<>""), N6/(50%+30%)*50% + O6/(50%+30%)*30%, "" ) ) ) ) ) ) + V6 ) -> #DIV/0! | K6: =IF(J6>=90,"A", IF(J6>=77,"B", IF(J6>=70,"C", IF(J6>=60,"D","E")))) -> #DIV/0! | L6: =_xlfn.RANK.EQ(J6,$J$2:$J$146,0) -> #DIV/0! | M6: =表格1_3[[#This Row],[部內平均]] -> #DIV/0! | O6: =表格1_3[[#This Row],[複評平均]] -> #DIV/0! | W6: 86 | X6: 4
A7: 移工 | B7: 2928 | C7: 夏塔拉 | D7: 塗裝組 | E7: 技術員 | F7: 郭惠燕 | G7: =表格1[[#This Row],[加權後總分]]-表格1[[#This Row],[獎懲分數]] -> #DIV/0! | H7: =IF(表格1[[#This Row],[不包含獎懲總分]]>=90,"A", IF(表格1[[#This Row],[不包含獎懲總分]]>=80,"B", IF(表格1[[#This Row],[不包含獎懲總分]]>=70,"C", IF(表格1[[#This Row],[不包含獎懲總分]]>=60,"D","E")))) -> #DIV/0! | I7: =_xlfn.RANK.EQ(G7,$G$2:$G$146,0) -> #DIV/0! | J7: =IF( AND(M7<>"",N7<>"",O7<>""), M7*20% + N7*50% + O7*30%, IF( AND(M7<>"",N7="",O7=""), M7, IF( AND(M7="",N7<>"",O7=""), N7, IF( AND(M7="",N7="",O7<>""), O7, IF( AND(M7<>"",N7<>"",O7=""), M7/(20%+50%)*20% + N7/(20%+50%)*50%, IF( AND(M7<>"",N7="",O7<>""), M7/(20%+30%)*20% + O7/(20%+30%)*30%, IF( AND(M7="",N7<>"",O7<>""), N7/(50%+30%)*50% + O7/(50%+30%)*30%, "" ) ) ) ) ) ) + V7 ) -> #DIV/0! | K7: =IF(J7>=90,"A", IF(J7>=77,"B", IF(J7>=70,"C", IF(J7>=60,"D","E")))) -> #DIV/0! | L7: =_xlfn.RANK.EQ(J7,$J$2:$J$146,0) -> #DIV/0! | M7: =表格1_3[[#This Row],[部內平均]] -> #DIV/0! | O7: =表格1_3[[#This Row],[複評平均]] -> #DIV/0! | W7: 85.8 | X7: 5
A8: 移工 | B8: 2968 | C8: 馬立泥 | D8: 塗裝組 | E8: 技術員 | F8: 郭惠燕 | G8: =表格1[[#This Row],[加權後總分]]-表格1[[#This Row],[獎懲分數]] -> #DIV/0! | H8: =IF(表格1[[#This Row],[不包含獎懲總分]]>=90,"A", IF(表格1[[#This Row],[不包含獎懲總分]]>=80,"B", IF(表格1[[#This Row],[不包含獎懲總分]]>=70,"C", IF(表格1[[#This Row],[不包含獎懲總分]]>=60,"D","E")))) -> #DIV/0! | I8: =_xlfn.RANK.EQ(G8,$G$2:$G$146,0) -> #DIV/0! | J8: =IF( AND(M8<>"",N8<>"",O8<>""), M8*20% + N8*50% + O8*30%, IF( AND(M8<>"",N8="",O8=""), M8, IF( AND(M8="",N8<>"",O8=""), N8, IF( AND(M8="",N8="",O8<>""), O8, IF( AND(M8<>"",N8<>"",O8=""), M8/(20%+50%)*20% + N8/(20%+50%)*50%, IF( AND(M8<>"",N8="",O8<>""), M8/(20%+30%)*20% + O8/(20%+30%)*30%, IF( AND(M8="",N8<>"",O8<>""), N8/(50%+30%)*50% + O8/(50%+30%)*30%, "" ) ) ) ) ) ) + V8 ) -> #DIV/0! | K8: =IF(J8>=90,"A", IF(J8>=77,"B", IF(J8>=70,"C", IF(J8>=60,"D","E")))) -> #DIV/0! | L8: =_xlfn.RANK.EQ(J8,$J$2:$J$146,0) -> #DIV/0! | M8: =表格1_3[[#This Row],[部內平均]] -> #DIV/0! | O8: =表格1_3[[#This Row],[複評平均]] -> #DIV/0! | W8: 84.866667 | X8: 6
A9: 移工 | B9: 3002 | C9: 肅坦 | D9: 塗裝組 | E9: 技術員 | F9: 白惇維 | G9: =表格1[[#This Row],[加權後總分]]-表格1[[#This Row],[獎懲分數]] -> #DIV/0! | H9: =IF(表格1[[#This Row],[不包含獎懲總分]]>=90,"A", IF(表格1[[#This Row],[不包含獎懲總分]]>=80,"B", IF(表格1[[#This Row],[不包含獎懲總分]]>=70,"C", IF(表格1[[#This Row],[不包含獎懲總分]]>=60,"D","E")))) -> #DIV/0! | I9: =_xlfn.RANK.EQ(G9,$G$2:$G$146,0) -> #DIV/0! | J9: =IF( AND(M9<>"",N9<>"",O9<>""), M9*20% + N9*50% + O9*30%, IF( AND(M9<>"",N9="",O9=""), M9, IF( AND(M9="",N9<>"",O9=""), N9, IF( AND(M9="",N9="",O9<>""), O9, IF( AND(M9<>"",N9<>"",O9=""), M9/(20%+50%)*20% + N9/(20%+50%)*50%, IF( AND(M9<>"",N9="",O9<>""), M9/(20%+30%)*20% + O9/(20%+30%)*30%, IF( AND(M9="",N9<>"",O9<>""), N9/(50%+30%)*50% + O9/(50%+30%)*30%, "" ) ) ) ) ) ) + V9 ) -> #DIV/0! | K9: =IF(J9>=90,"A", IF(J9>=77,"B", IF(J9>=70,"C", IF(J9>=60,"D","E")))) -> #DIV/0! | L9: =_xlfn.RANK.EQ(J9,$J$2:$J$146,0) -> #DIV/0! | M9: =表格1_3[[#This Row],[部內平均]] -> #DIV/0! | O9: =表格1_3[[#This Row],[複評平均]] -> #DIV/0! | W9: 84.8 | X9: 7
A10: 移工 | B10: 3003 | C10: 百翔 | D10: 塗裝組 | E10: 技術員 | F10: 白惇維 | G10: =表格1[[#This Row],[加權後總分]]-表格1[[#This Row],[獎懲分數]] -> #DIV/0! | H10: =IF(表格1[[#This Row],[不包含獎懲總分]]>=90,"A", IF(表格1[[#This Row],[不包含獎懲總分]]>=80,"B", IF(表格1[[#This Row],[不包含獎懲總分]]>=70,"C", IF(表格1[[#This Row],[不包含獎懲總分]]>=60,"D","E")))) -> #DIV/0! | I10: =_xlfn.RANK.EQ(G10,$G$2:$G$146,0) -> #DIV/0! | J10: =IF( AND(M10<>"",N10<>"",O10<>""), M10*20% + N10*50% + O10*30%, IF( AND(M10<>"",N10="",O10=""), M10, IF( AND(M10="",N10<>"",O10=""), N10, IF( AND(M10="",N10="",O10<>""), O10, IF( AND(M10<>"",N10<>"",O10=""), M10/(20%+50%)*20% + N10/(20%+50%)*50%, IF( AND(M10<>"",N10="",O10<>""), M10/(20%+30%)*20% + O10/(20%+30%)*30%, IF( AND(M10="",N10<>"",O10<>""), N10/(50%+30%)*50% + O10/(50%+30%)*30%, "" ) ) ) ) ) ) + V10 ) -> #DIV/0! | K10: =IF(J10>=90,"A", IF(J10>=77,"B", IF(J10>=70,"C", IF(J10>=60,"D","E")))) -> #DIV/0! | L10: =_xlfn.RANK.EQ(J10,$J$2:$J$146,0) -> #DIV/0! | M10: =表格1_3[[#This Row],[部內平均]] -> #DIV/0! | O10: =表格1_3[[#This Row],[複評平均]] -> #DIV/0! | W10: 83.8 | X10: 8
A11: 移工 | B11: 3005 | C11: 隆峽 | D11: 塗裝組 | E11: 技術員 | F11: 郭惠燕 | G11: =表格1[[#This Row],[加權後總分]]-表格1[[#This Row],[獎懲分數]] -> #DIV/0! | H11: =IF(表格1[[#This Row],[不包含獎懲總分]]>=90,"A", IF(表格1[[#This Row],[不包含獎懲總分]]>=80,"B", IF(表格1[[#This Row],[不包含獎懲總分]]>=70,"C", IF(表格1[[#This Row],[不包含獎懲總分]]>=60,"D","E")))) -> #DIV/0! | I11: =_xlfn.RANK.EQ(G11,$G$2:$G$146,0) -> #DIV/0! | J11: =IF( AND(M11<>"",N11<>"",O11<>""), M11*20% + N11*50% + O11*30%, IF( AND(M11<>"",N11="",O11=""), M11, IF( AND(M11="",N11<>"",O11=""), N11, IF( AND(M11="",N11="",O11<>""), O11, IF( AND(M11<>"",N11<>"",O11=""), M11/(20%+50%)*20% + N11/(20%+50%)*50%, IF( AND(M11<>"",N11="",O11<>""), M11/(20%+30%)*20% + O11/(20%+30%)*30%, IF( AND(M11="",N11<>"",O11<>""), N11/(50%+30%)*50% + O11/(50%+30%)*30%, "" ) ) ) ) ) ) + V11 ) -> #DIV/0! | K11: =IF(J11>=90,"A", IF(J11>=77,"B", IF(J11>=70,"C", IF(J11>=60,"D","E")))) -> #DIV/0! | L11: =_xlfn.RANK.EQ(J11,$J$2:$J$146,0) -> #DIV/0! | M11: =表格1_3[[#This Row],[部內平均]] -> #DIV/0! | O11: =表格1_3[[#This Row],[複評平均]] -> #DIV/0! | W11: 83.8 | X11: 9
A12: 移工 | B12: 2873 | C12: 松沙 | D12: 塗裝組 | E12: 技術員 | F12: 郭惠燕 | G12: =表格1[[#This Row],[加權後總分]]-表格1[[#This Row],[獎懲分數]] -> #DIV/0! | H12: =IF(表格1[[#This Row],[不包含獎懲總分]]>=90,"A", IF(表格1[[#This Row],[不包含獎懲總分]]>=80,"B", IF(表格1[[#This Row],[不包含獎懲總分]]>=70,"C", IF(表格1[[#This Row],[不包含獎懲總分]]>=60,"D","E")))) -> #DIV/0! | I12: =_xlfn.RANK.EQ(G12,$G$2:$G$146,0) -> #DIV/0! | J12: =IF( AND(M12<>"",N12<>"",O12<>""), M12*20% + N12*50% + O12*30%, IF( AND(M12<>"",N12="",O12=""), M12, IF( AND(M12="",N12<>"",O12=""), N12, IF( AND(M12="",N12="",O12<>""), O12, IF( AND(M12<>"",N12<>"",O12=""), M12/(20%+50%)*20% + N12/(20%+50%)*50%, IF( AND(M12<>"",N12="",O12<>""), M12/(20%+30%)*20% + O12/(20%+30%)*30%, IF( AND(M12="",N12<>"",O12<>""), N12/(50%+30%)*50% + O12/(50%+30%)*30%, "" ) ) ) ) ) ) + V12 ) -> #DIV/0! | K12: =IF(J12>=90,"A", IF(J12>=77,"B", IF(J12>=70,"C", IF(J12>=60,"D","E")))) -> #DIV/0! | L12: =_xlfn.RANK.EQ(J12,$J$2:$J$146,0) -> #DIV/0! | M12: =表格1_3[[#This Row],[部內平均]] -> #DIV/0! | O12: =表格1_3[[#This Row],[複評平均]] -> #DIV/0! | W12: 83.6 | X12: 10
A13: 移工 | B13: 2869 | C13: 宇藍南 | D13: 塗裝組 | E13: 技術員 | F13: 周清家 | G13: =表格1[[#This Row],[加權後總分]]-表格1[[#This Row],[獎懲分數]] -> #DIV/0! | H13: =IF(表格1[[#This Row],[不包含獎懲總分]]>=90,"A", IF(表格1[[#This Row],[不包含獎懲總分]]>=80,"B", IF(表格1[[#This Row],[不包含獎懲總分]]>=70,"C", IF(表格1[[#This Row],[不包含獎懲總分]]>=60,"D","E")))) -> #DIV/0! | I13: =_xlfn.RANK.EQ(G13,$G$2:$G$146,0) -> #DIV/0! | J13: =IF( AND(M13<>"",N13<>"",O13<>""), M13*20% + N13*50% + O13*30%, IF( AND(M13<>"",N13="",O13=""), M13, IF( AND(M13="",N13<>"",O13=""), N13, IF( AND(M13="",N13="",O13<>""), O13, IF( AND(M13<>"",N13<>"",O13=""), M13/(20%+50%)*20% + N13/(20%+50%)*50%, IF( AND(M13<>"",N13="",O13<>""), M13/(20%+30%)*20% + O13/(20%+30%)*30%, IF( AND(M13="",N13<>"",O13<>""), N13/(50%+30%)*50% + O13/(50%+30%)*30%, "" ) ) ) ) ) ) + V13 ) -> #DIV/0! | K13: =IF(J13>=90,"A", IF(J13>=77,"B", IF(J13>=70,"C", IF(J13>=60,"D","E")))) -> #DIV/0! | L13: =_xlfn.RANK.EQ(J13,$J$2:$J$146,0) -> #DIV/0! | M13: =表格1_3[[#This Row],[部內平均]] -> #DIV/0! | O13: =表格1_3[[#This Row],[複評平均]] -> #DIV/0! | W13: 83.6 | X13: 11
A14: 移工 | B14: 2909 | C14: 南龍裡 | D14: 塗裝組 | E14: 技術員 | F14: 郭惠燕 | G14: =表格1[[#This Row],[加權後總分]]-表格1[[#This Row],[獎懲分數]] -> #DIV/0! | H14: =IF(表格1[[#This Row],[不包含獎懲總分]]>=90,"A", IF(表格1[[#This Row],[不包含獎懲總分]]>=80,"B", IF(表格1[[#This Row],[不包含獎懲總分]]>=70,"C", IF(表格1[[#This Row],[不包含獎懲總分]]>=60,"D","E")))) -> #DIV/0! | I14: =_xlfn.RANK.EQ(G14,$G$2:$G$146,0) -> #DIV/0! | J14: =IF( AND(M14<>"",N14<>"",O14<>""), M14*20% + N14*50% + O14*30%, IF( AND(M14<>"",N14="",O14=""), M14, IF( AND(M14="",N14<>"",O14=""), N14, IF( AND(M14="",N14="",O14<>""), O14, IF( AND(M14<>"",N14<>"",O14=""), M14/(20%+50%)*20% + N14/(20%+50%)*50%, IF( AND(M14<>"",N14="",O14<>""), M14/(20%+30%)*20% + O14/(20%+30%)*30%, IF( AND(M14="",N14<>"",O14<>""), N14/(50%+30%)*50% + O14/(50%+30%)*30%, "" ) ) ) ) ) ) + V14 ) -> #DIV/0! | K14: =IF(J14>=90,"A", IF(J14>=77,"B", IF(J14>=70,"C", IF(J14>=60,"D","E")))) -> #DIV/0! | L14: =_xlfn.RANK.EQ(J14,$J$2:$J$146,0) -> #DIV/0! | M14: =表格1_3[[#This Row],[部內平均]] -> #DIV/0! | O14: =表格1_3[[#This Row],[複評平均]] -> #DIV/0! | W14: 82.8 | X14: 12
A15: 移工 | B15: 2910 | C15: 南天鵬 | D15: 塗裝組 | E15: 技術員 | F15: 周清家 | G15: =表格1[[#This Row],[加權後總分]]-表格1[[#This Row],[獎懲分數]] -> #DIV/0! | H15: =IF(表格1[[#This Row],[不包含獎懲總分]]>=90,"A", IF(表格1[[#This Row],[不包含獎懲總分]]>=80,"B", IF(表格1[[#This Row],[不包含獎懲總分]]>=70,"C", IF(表格1[[#This Row],[不包含獎懲總分]]>=60,"D","E")))) -> #DIV/0! | I15: =_xlfn.RANK.EQ(G15,$G$2:$G$146,0) -> #DIV/0! | J15: =IF( AND(M15<>"",N15<>"",O15<>""), M15*20% + N15*50% + O15*30%, IF( AND(M15<>"",N15="",O15=""), M15, IF( AND(M15="",N15<>"",O15=""), N15, IF( AND(M15="",N15="",O15<>""), O15, IF( AND(M15<>"",N15<>"",O15=""), M15/(20%+50%)*20% + N15/(20%+50%)*50%, IF( AND(M15<>"",N15="",O15<>""), M15/(20%+30%)*20% + O15/(20%+30%)*30%, IF( AND(M15="",N15<>"",O15<>""), N15/(50%+30%)*50% + O15/(50%+30%)*30%, "" ) ) ) ) ) ) + V15 ) -> #DIV/0! | K15: =IF(J15>=90,"A", IF(J15>=77,"B", IF(J15>=70,"C", IF(J15>=60,"D","E")))) -> #DIV/0! | L15: =_xlfn.RANK.EQ(J15,$J$2:$J$146,0) -> #DIV/0! | M15: =表格1_3[[#This Row],[部內平均]] -> #DIV/0! | O15: =表格1_3[[#This Row],[複評平均]] -> #DIV/0! | W15: 82.2 | X15: 13
A16: 移工 | B16: 2776 | C16: 陳俊智 | D16: 塗裝組 | E16: 技術員 | F16: 郭惠燕 | G16: =表格1[[#This Row],[加權後總分]]-表格1[[#This Row],[獎懲分數]] -> #DIV/0! | H16: =IF(表格1[[#This Row],[不包含獎懲總分]]>=90,"A", IF(表格1[[#This Row],[不包含獎懲總分]]>=80,"B", IF(表格1[[#This Row],[不包含獎懲總分]]>=70,"C", IF(表格1[[#This Row],[不包含獎懲總分]]>=60,"D","E")))) -> #DIV/0! | I16: =_xlfn.RANK.EQ(G16,$G$2:$G$146,0) -> #DIV/0! | J16: =IF( AND(M16<>"",N16<>"",O16<>""), M16*20% + N16*50% + O16*30%, IF( AND(M16<>"",N16="",O16=""), M16, IF( AND(M16="",N16<>"",O16=""), N16, IF( AND(M16="",N16="",O16<>""), O16, IF( AND(M16<>"",N16<>"",O16=""), M16/(20%+50%)*20% + N16/(20%+50%)*50%, IF( AND(M16<>"",N16="",O16<>""), M16/(20%+30%)*20% + O16/(20%+30%)*30%, IF( AND(M16="",N16<>"",O16<>""), N16/(50%+30%)*50% + O16/(50%+30%)*30%, "" ) ) ) ) ) ) + V16 ) -> #DIV/0! | K16: =IF(J16>=90,"A", IF(J16>=77,"B", IF(J16>=70,"C", IF(J16>=60,"D","E")))) -> #DIV/0! | L16: =_xlfn.RANK.EQ(J16,$J$2:$J$146,0) -> #DIV/0! | M16: =表格1_3[[#This Row],[部內平均]] -> #DIV/0! | O16: =表格1_3[[#This Row],[複評平均]] -> #DIV/0! | W16: 81.4 | X16: 14
A17: 移工 | B17: 2832 | C17: 阿迪朋 | D17: 塗裝組 | E17: 技術員 | F17: 陳佳安 | G17: =表格1[[#This Row],[加權後總分]]-表格1[[#This Row],[獎懲分數]] -> #DIV/0! | H17: =IF(表格1[[#This Row],[不包含獎懲總分]]>=90,"A", IF(表格1[[#This Row],[不包含獎懲總分]]>=80,"B", IF(表格1[[#This Row],[不包含獎懲總分]]>=70,"C", IF(表格1[[#This Row],[不包含獎懲總分]]>=60,"D","E")))) -> #DIV/0! | I17: =_xlfn.RANK.EQ(G17,$G$2:$G$146,0) -> #DIV/0! | J17: =IF( AND(M17<>"",N17<>"",O17<>""), M17*20% + N17*50% + O17*30%, IF( AND(M17<>"",N17="",O17=""), M17, IF( AND(M17="",N17<>"",O17=""), N17, IF( AND(M17="",N17="",O17<>""), O17, IF( AND(M17<>"",N17<>"",O17=""), M17/(20%+50%)*20% + N17/(20%+50%)*50%, IF( AND(M17<>"",N17="",O17<>""), M17/(20%+30%)*20% + O17/(20%+30%)*30%, IF( AND(M17="",N17<>"",O17<>""), N17/(50%+30%)*50% + O17/(50%+30%)*30%, "" ) ) ) ) ) ) + V17 ) -> #DIV/0! | K17: =IF(J17>=90,"A", IF(J17>=77,"B", IF(J17>=70,"C", IF(J17>=60,"D","E")))) -> #DIV/0! | L17: =_xlfn.RANK.EQ(J17,$J$2:$J$146,0) -> #DIV/0! | M17: =表格1_3[[#This Row],[部內平均]] -> #DIV/0! | O17: =表格1_3[[#This Row],[複評平均]] -> #DIV/0! | W17: 81.35 | X17: 15
A18: 移工 | B18: 2834 | C18: 阿沙文 | D18: 塗裝組 | E18: 技術員 | F18: 郭惠燕 | G18: =表格1[[#This Row],[加權後總分]]-表格1[[#This Row],[獎懲分數]] -> #DIV/0! | H18: =IF(表格1[[#This Row],[不包含獎懲總分]]>=90,"A", IF(表格1[[#This Row],[不包含獎懲總分]]>=80,"B", IF(表格1[[#This Row],[不包含獎懲總分]]>=70,"C", IF(表格1[[#This Row],[不包含獎懲總分]]>=60,"D","E")))) -> #DIV/0! | I18: =_xlfn.RANK.EQ(G18,$G$2:$G$146,0) -> #DIV/0! | J18: =IF( AND(M18<>"",N18<>"",O18<>""), M18*20% + N18*50% + O18*30%, IF( AND(M18<>"",N18="",O18=""), M18, IF( AND(M18="",N18<>"",O18=""), N18, IF( AND(M18="",N18="",O18<>""), O18, IF( AND(M18<>"",N18<>"",O18=""), M18/(20%+50%)*20% + N18/(20%+50%)*50%, IF( AND(M18<>"",N18="",O18<>""), M18/(20%+30%)*20% + O18/(20%+30%)*30%, IF( AND(M18="",N18<>"",O18<>""), N18/(50%+30%)*50% + O18/(50%+30%)*30%, "" ) ) ) ) ) ) + V18 ) -> #DIV/0! | K18: =IF(J18>=90,"A", IF(J18>=77,"B", IF(J18>=70,"C", IF(J18>=60,"D","E")))) -> #DIV/0! | L18: =_xlfn.RANK.EQ(J18,$J$2:$J$146,0) -> #DIV/0! | M18: =表格1_3[[#This Row],[部內平均]] -> #DIV/0! | O18: =表格1_3[[#This Row],[複評平均]] -> #DIV/0! | W18: 81.058333 | X18: 16
G19: =表格1[[#This Row],[加權後總分]]-表格1[[#This Row],[獎懲分數]] -> #DIV/0! | H19: =IF(表格1[[#This Row],[不包含獎懲總分]]>=90,"A", IF(表格1[[#This Row],[不包含獎懲總分]]>=80,"B", IF(表格1[[#This Row],[不包含獎懲總分]]>=70,"C", IF(表格1[[#This Row],[不包含獎懲總分]]>=60,"D","E")))) -> #DIV/0! | I19: =_xlfn.RANK.EQ(G19,$G$2:$G$146,0) -> #DIV/0! | J19: =IF( AND(M19<>"",N19<>"",O19<>""), M19*20% + N19*50% + O19*30%, IF( AND(M19<>"",N19="",O19=""), M19, IF( AND(M19="",N19<>"",O19=""), N19, IF( AND(M19="",N19="",O19<>""), O19, IF( AND(M19<>"",N19<>"",O19=""), M19/(20%+50%)*20% + N19/(20%+50%)*50%, IF( AND(M19<>"",N19="",O19<>""), M19/(20%+30%)*20% + O19/(20%+30%)*30%, IF( AND(M19="",N19<>"",O19<>""), N19/(50%+30%)*50% + O19/(50%+30%)*30%, "" ) ) ) ) ) ) + V19 ) -> #DIV/0! | K19: =IF(J19>=90,"A", IF(J19>=77,"B", IF(J19>=70,"C", IF(J19>=60,"D","E")))) -> #DIV/0! | L19: =_xlfn.RANK.EQ(J19,$J$2:$J$146,0) -> #DIV/0! | M19: =表格1_3[[#This Row],[部內平均]] -> #DIV/0! | O19: =表格1_3[[#This Row],[複評平均]] -> #DIV/0! | W19: 80.693878 | X19: 17
B20: 1713 | C20: 周安琪 | D20: 塗裝組 | E20: 班長 | F20: 郭惠燕 | G20: =表格1[[#This Row],[加權後總分]]-表格1[[#This Row],[獎懲分數]] -> #DIV/0! | H20: =IF(表格1[[#This Row],[不包含獎懲總分]]>=90,"A", IF(表格1[[#This Row],[不包含獎懲總分]]>=80,"B", IF(表格1[[#This Row],[不包含獎懲總分]]>=70,"C", IF(表格1[[#This Row],[不包含獎懲總分]]>=60,"D","E")))) -> #DIV/0! | I20: =_xlfn.RANK.EQ(G20,$G$2:$G$146,0) -> #DIV/0! | J20: =IF( AND(M20<>"",N20<>"",O20<>""), M20*20% + N20*50% + O20*30%, IF( AND(M20<>"",N20="",O20=""), M20, IF( AND(M20="",N20<>"",O20=""), N20, IF( AND(M20="",N20="",O20<>""), O20, IF( AND(M20<>"",N20<>"",O20=""), M20/(20%+50%)*20% + N20/(20%+50%)*50%, IF( AND(M20<>"",N20="",O20<>""), M20/(20%+30%)*20% + O20/(20%+30%)*30%, IF( AND(M20="",N20<>"",O20<>""), N20/(50%+30%)*50% + O20/(50%+30%)*30%, "" ) ) ) ) ) ) + V20 ) -> #DIV/0! | K20: =IF(J20>=90,"A", IF(J20>=77,"B", IF(J20>=70,"C", IF(J20>=60,"D","E")))) -> #DIV/0! | L20: =_xlfn.RANK.EQ(J20,$J$2:$J$146,0) -> #DIV/0! | M20: =表格1_3[[#This Row],[部內平均]] -> #DIV/0! | N20: =表格1_3[[#This Row],[共評平均]] -> #DIV/0! | O20: =表格1_3[[#This Row],[複評平均]] -> #DIV/0! | W20: 80.6 | X20: 18
A21: 外配 | B21: 2546 | C21: 黃氏金莉 | D21: 塗裝組 | E21: 技術員 | F21: 郭惠燕 | G21: =表格1[[#This Row],[加權後總分]]-表格1[[#This Row],[獎懲分數]] -> #DIV/0! | H21: =IF(表格1[[#This Row],[不包含獎懲總分]]>=90,"A", IF(表格1[[#This Row],[不包含獎懲總分]]>=80,"B", IF(表格1[[#This Row],[不包含獎懲總分]]>=70,"C", IF(表格1[[#This Row],[不包含獎懲總分]]>=60,"D","E")))) -> #DIV/0! | I21: =_xlfn.RANK.EQ(G21,$G$2:$G$146,0) -> #DIV/0! | J21: =IF( AND(M21<>"",N21<>"",O21<>""), M21*20% + N21*50% + O21*30%, IF( AND(M21<>"",N21="",O21=""), M21, IF( AND(M21="",N21<>"",O21=""), N21, IF( AND(M21="",N21="",O21<>""), O21, IF( AND(M21<>"",N21<>"",O21=""), M21/(20%+50%)*20% + N21/(20%+50%)*50%, IF( AND(M21<>"",N21="",O21<>""), M21/(20%+30%)*20% + O21/(20%+30%)*30%, IF( AND(M21="",N21<>"",O21<>""), N21/(50%+30%)*50% + O21/(50%+30%)*30%, "" ) ) ) ) ) ) + V21 ) -> #DIV/0! | K21: =IF(J21>=90,"A", IF(J21>=77,"B", IF(J21>=70,"C", IF(J21>=60,"D","E")))) -> #DIV/0! | L21: =_xlfn.RANK.EQ(J21,$J$2:$J$146,0) -> #DIV/0! | M21: =表格1_3[[#This Row],[部內平均]] -> #DIV/0! | O21: =表格1_3[[#This Row],[複評平均]] -> #DIV/0! | W21: 80.5 | X21: 19
A22: 移工 | B22: 2589 | C22: 威耐 | D22: 塗裝組 | E22: 班長 | F22: 郭惠燕 | G22: =表格1[[#This Row],[加權後總分]]-表格1[[#This Row],[獎懲分數]] -> #DIV/0! | H22: =IF(表格1[[#This Row],[不包含獎懲總分]]>=90,"A", IF(表格1[[#This Row],[不包含獎懲總分]]>=80,"B", IF(表格1[[#This Row],[不包含獎懲總分]]>=70,"C", IF(表格1[[#This Row],[不包含獎懲總分]]>=60,"D","E")))) -> #DIV/0! | I22: =_xlfn.RANK.EQ(G22,$G$2:$G$146,0) -> #DIV/0! | J22: =IF( AND(M22<>"",N22<>"",O22<>""), M22*20% + N22*50% + O22*30%, IF( AND(M22<>"",N22="",O22=""), M22, IF( AND(M22="",N22<>"",O22=""), N22, IF( AND(M22="",N22="",O22<>""), O22, IF( AND(M22<>"",N22<>"",O22=""), M22/(20%+50%)*20% + N22/(20%+50%)*50%, IF( AND(M22<>"",N22="",O22<>""), M22/(20%+30%)*20% + O22/(20%+30%)*30%, IF( AND(M22="",N22<>"",O22<>""), N22/(50%+30%)*50% + O22/(50%+30%)*30%, "" ) ) ) ) ) ) + V22 ) -> #DIV/0! | K22: =IF(J22>=90,"A", IF(J22>=77,"B", IF(J22>=70,"C", IF(J22>=60,"D","E")))) -> #DIV/0! | L22: =_xlfn.RANK.EQ(J22,$J$2:$J$146,0) -> #DIV/0! | M22: =表格1_3[[#This Row],[部內平均]] -> #DIV/0! | N22: =表格1_3[[#This Row],[共評平均]] -> #DIV/0! | O22: =表格1_3[[#This Row],[複評平均]] -> #DIV/0! | W22: 79.938776 | X22: 20
B23: 1101 | C23: 郭惠燕 | D23: 塗裝組 | E23: 組長 | F23: 周清家 | G23: =表格1[[#This Row],[加權後總分]]-表格1[[#This Row],[獎懲分數]] -> #DIV/0! | H23: =IF(表格1[[#This Row],[不包含獎懲總分]]>=90,"A", IF(表格1[[#This Row],[不包含獎懲總分]]>=80,"B", IF(表格1[[#This Row],[不包含獎懲總分]]>=70,"C", IF(表格1[[#This Row],[不包含獎懲總分]]>=60,"D","E")))) -> #DIV/0! | I23: =_xlfn.RANK.EQ(G23,$G$2:$G$146,0) -> #DIV/0! | J23: =IF( AND(M23<>"",N23<>"",O23<>""), M23*20% + N23*50% + O23*30%, IF( AND(M23<>"",N23="",O23=""), M23, IF( AND(M23="",N23<>"",O23=""), N23, IF( AND(M23="",N23="",O23<>""), O23, IF( AND(M23<>"",N23<>"",O23=""), M23/(20%+50%)*20% + N23/(20%+50%)*50%, IF( AND(M23<>"",N23="",O23<>""), M23/(20%+30%)*20% + O23/(20%+30%)*30%, IF( AND(M23="",N23<>"",O23<>""), N23/(50%+30%)*50% + O23/(50%+30%)*30%, "" ) ) ) ) ) ) + V23 ) -> #DIV/0! | K23: =IF(J23>=90,"A", IF(J23>=77,"B", IF(J23>=70,"C", IF(J23>=60,"D","E")))) -> #DIV/0! | L23: =_xlfn.RANK.EQ(J23,$J$2:$J$146,0) -> #DIV/0! | M23: =表格1_3[[#This Row],[部內平均]] -> #DIV/0! | N23: =表格1_3[[#This Row],[共評平均]] -> #DIV/0! | O23: =表格1_3[[#This Row],[複評平均]] -> #DIV/0! | W23: 79.416667 | X23: 21
A24: 現場 | B24: 2056 | C24: 陳世傑 | D24: 塗裝組 | E24: 技術員 | F24: 郭惠燕 | G24: =表格1[[#This Row],[加權後總分]]-表格1[[#This Row],[獎懲分數]] -> #DIV/0! | H24: =IF(表格1[[#This Row],[不包含獎懲總分]]>=90,"A", IF(表格1[[#This Row],[不包含獎懲總分]]>=80,"B", IF(表格1[[#This Row],[不包含獎懲總分]]>=70,"C", IF(表格1[[#This Row],[不包含獎懲總分]]>=60,"D","E")))) -> #DIV/0! | I24: =_xlfn.RANK.EQ(G24,$G$2:$G$146,0) -> #DIV/0! | J24: =IF( AND(M24<>"",N24<>"",O24<>""), M24*20% + N24*50% + O24*30%, IF( AND(M24<>"",N24="",O24=""), M24, IF( AND(M24="",N24<>"",O24=""), N24, IF( AND(M24="",N24="",O24<>""), O24, IF( AND(M24<>"",N24<>"",O24=""), M24/(20%+50%)*20% + N24/(20%+50%)*50%, IF( AND(M24<>"",N24="",O24<>""), M24/(20%+30%)*20% + O24/(20%+30%)*30%, IF( AND(M24="",N24<>"",O24<>""), N24/(50%+30%)*50% + O24/(50%+30%)*30%, "" ) ) ) ) ) ) + V24 ) -> #DIV/0! | K24: =IF(J24>=90,"A", IF(J24>=77,"B", IF(J24>=70,"C", IF(J24>=60,"D","E")))) -> #DIV/0! | L24: =_xlfn.RANK.EQ(J24,$J$2:$J$146,0) -> #DIV/0! | M24: =表格1_3[[#This Row],[部內平均]] -> #DIV/0! | O24: =表格1_3[[#This Row],[複評平均]] -> #DIV/0! | W24: 79.285714 | X24: 22
A25: 外配 | B25: 2258 | C25: 連維敏 | D25: 組一組 | E25: 技術員 | F25: 陳佳安 | G25: =表格1[[#This Row],[加權後總分]]-表格1[[#This Row],[獎懲分數]] -> #DIV/0! | H25: =IF(表格1[[#This Row],[不包含獎懲總分]]>=90,"A", IF(表格1[[#This Row],[不包含獎懲總分]]>=80,"B", IF(表格1[[#This Row],[不包含獎懲總分]]>=70,"C", IF(表格1[[#This Row],[不包含獎懲總分]]>=60,"D","E")))) -> #DIV/0! | I25: =_xlfn.RANK.EQ(G25,$G$2:$G$146,0) -> #DIV/0! | J25: =IF( AND(M25<>"",N25<>"",O25<>""), M25*20% + N25*50% + O25*30%, IF( AND(M25<>"",N25="",O25=""), M25, IF( AND(M25="",N25<>"",O25=""), N25, IF( AND(M25="",N25="",O25<>""), O25, IF( AND(M25<>"",N25<>"",O25=""), M25/(20%+50%)*20% + N25/(20%+50%)*50%, IF( AND(M25<>"",N25="",O25<>""), M25/(20%+30%)*20% + O25/(20%+30%)*30%, IF( AND(M25="",N25<>"",O25<>""), N25/(50%+30%)*50% + O25/(50%+30%)*30%, "" ) ) ) ) ) ) + V25 ) -> #DIV/0! | K25: =IF(J25>=90,"A", IF(J25>=77,"B", IF(J25>=70,"C", IF(J25>=60,"D","E")))) -> #DIV/0! | L25: =_xlfn.RANK.EQ(J25,$J$2:$J$146,0) -> #DIV/0! | M25: =表格1_3[[#This Row],[部內平均]] -> #DIV/0! | O25: =表格1_3[[#This Row],[複評平均]] -> #DIV/0! | W25: 79.109091 | X25: 23
A26: 現場 | B26: 1799 | C26: 朱淑君 | D26: 組一組 | E26: 技術員 | F26: 陳怡珊 | G26: =表格1[[#This Row],[加權後總分]]-表格1[[#This Row],[獎懲分數]] -> #DIV/0! | H26: =IF(表格1[[#This Row],[不包含獎懲總分]]>=90,"A", IF(表格1[[#This Row],[不包含獎懲總分]]>=80,"B", IF(表格1[[#This Row],[不包含獎懲總分]]>=70,"C", IF(表格1[[#This Row],[不包含獎懲總分]]>=60,"D","E")))) -> #DIV/0! | I26: =_xlfn.RANK.EQ(G26,$G$2:$G$146,0) -> #DIV/0! | J26: =IF( AND(M26<>"",N26<>"",O26<>""), M26*20% + N26*50% + O26*30%, IF( AND(M26<>"",N26="",O26=""), M26, IF( AND(M26="",N26<>"",O26=""), N26, IF( AND(M26="",N26="",O26<>""), O26, IF( AND(M26<>"",N26<>"",O26=""), M26/(20%+50%)*20% + N26/(20%+50%)*50%, IF( AND(M26<>"",N26="",O26<>""), M26/(20%+30%)*20% + O26/(20%+30%)*30%, IF( AND(M26="",N26<>"",O26<>""), N26/(50%+30%)*50% + O26/(50%+30%)*30%, "" ) ) ) ) ) ) + V26 ) -> #DIV/0! | K26: =IF(J26>=90,"A", IF(J26>=77,"B", IF(J26>=70,"C", IF(J26>=60,"D","E")))) -> #DIV/0! | L26: =_xlfn.RANK.EQ(J26,$J$2:$J$146,0) -> #DIV/0! | M26: =表格1_3[[#This Row],[部內平均]] -> #DIV/0! | O26: =表格1_3[[#This Row],[複評平均]] -> #DIV/0! | W26: 79 | X26: 24
A27: 現場 | B27: 2565 | C27: 呂雅秀 | D27: 組一組 | E27: 技術員 | F27: 陳佳安 | G27: =表格1[[#This Row],[加權後總分]]-表格1[[#This Row],[獎懲分數]] -> #DIV/0! | H27: =IF(表格1[[#This Row],[不包含獎懲總分]]>=90,"A", IF(表格1[[#This Row],[不包含獎懲總分]]>=80,"B", IF(表格1[[#This Row],[不包含獎懲總分]]>=70,"C", IF(表格1[[#This Row],[不包含獎懲總分]]>=60,"D","E")))) -> #DIV/0! | I27: =_xlfn.RANK.EQ(G27,$G$2:$G$146,0) -> #DIV/0! | J27: =IF( AND(M27<>"",N27<>"",O27<>""), M27*20% + N27*50% + O27*30%, IF( AND(M27<>"",N27="",O27=""), M27, IF( AND(M27="",N27<>"",O27=""), N27, IF( AND(M27="",N27="",O27<>""), O27, IF( AND(M27<>"",N27<>"",O27=""), M27/(20%+50%)*20% + N27/(20%+50%)*50%, IF( AND(M27<>"",N27="",O27<>""), M27/(20%+30%)*20% + O27/(20%+30%)*30%, IF( AND(M27="",N27<>"",O27<>""), N27/(50%+30%)*50% + O27/(50%+30%)*30%, "" ) ) ) ) ) ) + V27 ) -> #DIV/0! | K27: =IF(J27>=90,"A", IF(J27>=77,"B", IF(J27>=70,"C", IF(J27>=60,"D","E")))) -> #DIV/0! | L27: =_xlfn.RANK.EQ(J27,$J$2:$J$146,0) -> #DIV/0! | M27: =表格1_3[[#This Row],[部內平均]] -> #DIV/0! | O27: =表格1_3[[#This Row],[複評平均]] -> #DIV/0! | W27: 78.957143 | X27: 25
A28: 移工 | B28: 2418 | C28: 松甲 | D28: 組一組 | E28: 技術員 | F28: 陳佳安 | G28: =表格1[[#This Row],[加權後總分]]-表格1[[#This Row],[獎懲分數]] -> #DIV/0! | H28: =IF(表格1[[#This Row],[不包含獎懲總分]]>=90,"A", IF(表格1[[#This Row],[不包含獎懲總分]]>=80,"B", IF(表格1[[#This Row],[不包含獎懲總分]]>=70,"C", IF(表格1[[#This Row],[不包含獎懲總分]]>=60,"D","E")))) -> #DIV/0! | I28: =_xlfn.RANK.EQ(G28,$G$2:$G$146,0) -> #DIV/0! | J28: =IF( AND(M28<>"",N28<>"",O28<>""), M28*20% + N28*50% + O28*30%, IF( AND(M28<>"",N28="",O28=""), M28, IF( AND(M28="",N28<>"",O28=""), N28, IF( AND(M28="",N28="",O28<>""), O28, IF( AND(M28<>"",N28<>"",O28=""), M28/(20%+50%)*20% + N28/(20%+50%)*50%, IF( AND(M28<>"",N28="",O28<>""), M28/(20%+30%)*20% + O28/(20%+30%)*30%, IF( AND(M28="",N28<>"",O28<>""), N28/(50%+30%)*50% + O28/(50%+30%)*30%, "" ) ) ) ) ) ) + V28 ) -> #DIV/0! | K28: =IF(J28>=90,"A", IF(J28>=77,"B", IF(J28>=70,"C", IF(J28>=60,"D","E")))) -> #DIV/0! | L28: =_xlfn.RANK.EQ(J28,$J$2:$J$146,0) -> #DIV/0! | M28: =表格1_3[[#This Row],[部內平均]] -> #DIV/0! | O28: =表格1_3[[#This Row],[複評平均]] -> #DIV/0! | W28: 78.732143 | X28: 26
A29: 現場 | B29: 2226 | C29: 陳意琛 | D29: 組一組 | E29: 技術員 | F29: 陳佳安 | G29: =表格1[[#This Row],[加權後總分]]-表格1[[#This Row],[獎懲分數]] -> #DIV/0! | H29: =IF(表格1[[#This Row],[不包含獎懲總分]]>=90,"A", IF(表格1[[#This Row],[不包含獎懲總分]]>=80,"B", IF(表格1[[#This Row],[不包含獎懲總分]]>=70,"C", IF(表格1[[#This Row],[不包含獎懲總分]]>=60,"D","E")))) -> #DIV/0! | I29: =_xlfn.RANK.EQ(G29,$G$2:$G$146,0) -> #DIV/0! | J29: =IF( AND(M29<>"",N29<>"",O29<>""), M29*20% + N29*50% + O29*30%, IF( AND(M29<>"",N29="",O29=""), M29, IF( AND(M29="",N29<>"",O29=""), N29, IF( AND(M29="",N29="",O29<>""), O29, IF( AND(M29<>"",N29<>"",O29=""), M29/(20%+50%)*20% + N29/(20%+50%)*50%, IF( AND(M29<>"",N29="",O29<>""), M29/(20%+30%)*20% + O29/(20%+30%)*30%, IF( AND(M29="",N29<>"",O29<>""), N29/(50%+30%)*50% + O29/(50%+30%)*30%, "" ) ) ) ) ) ) + V29 ) -> #DIV/0! | K29: =IF(J29>=90,"A", IF(J29>=77,"B", IF(J29>=70,"C", IF(J29>=60,"D","E")))) -> #DIV/0! | L29: =_xlfn.RANK.EQ(J29,$J$2:$J$146,0) -> #DIV/0! | M29: =表格1_3[[#This Row],[部內平均]] -> #DIV/0! | O29: =表格1_3[[#This Row],[複評平均]] -> #DIV/0! | W29: 78.2 | X29: 27
A30: 移工 | B30: 2827 | C30: 蘇拉岡 | D30: 組一組 | E30: 技術員 | F30: 陳佳安 | G30: =表格1[[#This Row],[加權後總分]]-表格1[[#This Row],[獎懲分數]] -> #DIV/0! | H30: =IF(表格1[[#This Row],[不包含獎懲總分]]>=90,"A", IF(表格1[[#This Row],[不包含獎懲總分]]>=80,"B", IF(表格1[[#This Row],[不包含獎懲總分]]>=70,"C", IF(表格1[[#This Row],[不包含獎懲總分]]>=60,"D","E")))) -> #DIV/0! | I30: =_xlfn.RANK.EQ(G30,$G$2:$G$146,0) -> #DIV/0! | J30: =IF( AND(M30<>"",N30<>"",O30<>""), M30*20% + N30*50% + O30*30%, IF( AND(M30<>"",N30="",O30=""), M30, IF( AND(M30="",N30<>"",O30=""), N30, IF( AND(M30="",N30="",O30<>""), O30, IF( AND(M30<>"",N30<>"",O30=""), M30/(20%+50%)*20% + N30/(20%+50%)*50%, IF( AND(M30<>"",N30="",O30<>""), M30/(20%+30%)*20% + O30/(20%+30%)*30%, IF( AND(M30="",N30<>"",O30<>""), N30/(50%+30%)*50% + O30/(50%+30%)*30%, "" ) ) ) ) ) ) + V30 ) -> #DIV/0! | K30: =IF(J30>=90,"A", IF(J30>=77,"B", IF(J30>=70,"C", IF(J30>=60,"D","E")))) -> #DIV/0! | L30: =_xlfn.RANK.EQ(J30,$J$2:$J$146,0) -> #DIV/0! | M30: =表格1_3[[#This Row],[部內平均]] -> #DIV/0! | O30: =表格1_3[[#This Row],[複評平均]] -> #DIV/0! | W30: 77.8 | X30: 28
A31: 現場 | B31: 2724 | C31: 周柏杰 | D31: 組一組 | E31: 技術員 | F31: 陳佳安 | G31: =表格1[[#This Row],[加權後總分]]-表格1[[#This Row],[獎懲分數]] -> #DIV/0! | H31: =IF(表格1[[#This Row],[不包含獎懲總分]]>=90,"A", IF(表格1[[#This Row],[不包含獎懲總分]]>=80,"B", IF(表格1[[#This Row],[不包含獎懲總分]]>=70,"C", IF(表格1[[#This Row],[不包含獎懲總分]]>=60,"D","E")))) -> #DIV/0! | I31: =_xlfn.RANK.EQ(G31,$G$2:$G$146,0) -> #DIV/0! | J31: =IF( AND(M31<>"",N31<>"",O31<>""), M31*20% + N31*50% + O31*30%, IF( AND(M31<>"",N31="",O31=""), M31, IF( AND(M31="",N31<>"",O31=""), N31, IF( AND(M31="",N31="",O31<>""), O31, IF( AND(M31<>"",N31<>"",O31=""), M31/(20%+50%)*20% + N31/(20%+50%)*50%, IF( AND(M31<>"",N31="",O31<>""), M31/(20%+30%)*20% + O31/(20%+30%)*30%, IF( AND(M31="",N31<>"",O31<>""), N31/(50%+30%)*50% + O31/(50%+30%)*30%, "" ) ) ) ) ) ) + V31 ) -> #DIV/0! | K31: =IF(J31>=90,"A", IF(J31>=77,"B", IF(J31>=70,"C", IF(J31>=60,"D","E")))) -> #DIV/0! | L31: =_xlfn.RANK.EQ(J31,$J$2:$J$146,0) -> #DIV/0! | M31: =表格1_3[[#This Row],[部內平均]] -> #DIV/0! | O31: =表格1_3[[#This Row],[複評平均]] -> #DIV/0! | W31: 77.6 | X31: 29
A32: 移工 | B32: 3004 | C32: 朗吾 | D32: 組一組 | E32: 技術員 | F32: 陳怡珊 | G32: =表格1[[#This Row],[加權後總分]]-表格1[[#This Row],[獎懲分數]] -> #DIV/0! | H32: =IF(表格1[[#This Row],[不包含獎懲總分]]>=90,"A", IF(表格1[[#This Row],[不包含獎懲總分]]>=80,"B", IF(表格1[[#This Row],[不包含獎懲總分]]>=70,"C", IF(表格1[[#This Row],[不包含獎懲總分]]>=60,"D","E")))) -> #DIV/0! | I32: =_xlfn.RANK.EQ(G32,$G$2:$G$146,0) -> #DIV/0! | J32: =IF( AND(M32<>"",N32<>"",O32<>""), M32*20% + N32*50% + O32*30%, IF( AND(M32<>"",N32="",O32=""), M32, IF( AND(M32="",N32<>"",O32=""), N32, IF( AND(M32="",N32="",O32<>""), O32, IF( AND(M32<>"",N32<>"",O32=""), M32/(20%+50%)*20% + N32/(20%+50%)*50%, IF( AND(M32<>"",N32="",O32<>""), M32/(20%+30%)*20% + O32/(20%+30%)*30%, IF( AND(M32="",N32<>"",O32<>""), N32/(50%+30%)*50% + O32/(50%+30%)*30%, "" ) ) ) ) ) ) + V32 ) -> #DIV/0! | K32: =IF(J32>=90,"A", IF(J32>=77,"B", IF(J32>=70,"C", IF(J32>=60,"D","E")))) -> #DIV/0! | L32: =_xlfn.RANK.EQ(J32,$J$2:$J$146,0) -> #DIV/0! | M32: =表格1_3[[#This Row],[部內平均]] -> #DIV/0! | O32: =表格1_3[[#This Row],[複評平均]] -> #DIV/0! | W32: 77.4 | X32: 30
G33: =表格1[[#This Row],[加權後總分]]-表格1[[#This Row],[獎懲分數]] -> #DIV/0! | H33: =IF(表格1[[#This Row],[不包含獎懲總分]]>=90,"A", IF(表格1[[#This Row],[不包含獎懲總分]]>=80,"B", IF(表格1[[#This Row],[不包含獎懲總分]]>=70,"C", IF(表格1[[#This Row],[不包含獎懲總分]]>=60,"D","E")))) -> #DIV/0! | I33: =_xlfn.RANK.EQ(G33,$G$2:$G$146,0) -> #DIV/0! | J33: =IF( AND(M33<>"",N33<>"",O33<>""), M33*20% + N33*50% + O33*30%, IF( AND(M33<>"",N33="",O33=""), M33, IF( AND(M33="",N33<>"",O33=""), N33, IF( AND(M33="",N33="",O33<>""), O33, IF( AND(M33<>"",N33<>"",O33=""), M33/(20%+50%)*20% + N33/(20%+50%)*50%, IF( AND(M33<>"",N33="",O33<>""), M33/(20%+30%)*20% + O33/(20%+30%)*30%, IF( AND(M33="",N33<>"",O33<>""), N33/(50%+30%)*50% + O33/(50%+30%)*30%, "" ) ) ) ) ) ) + V33 ) -> #DIV/0! | K33: =IF(J33>=90,"A", IF(J33>=77,"B", IF(J33>=70,"C", IF(J33>=60,"D","E")))) -> #DIV/0! | L33: =_xlfn.RANK.EQ(J33,$J$2:$J$146,0) -> #DIV/0! | M33: =表格1_3[[#This Row],[部內平均]] -> #DIV/0! | O33: =表格1_3[[#This Row],[複評平均]] -> #DIV/0!
A34: 移工 | B34: 2930 | C34: 巴林亞 | D34: 組一組 | E34: 技術員 | F34: 陳怡珊 | G34: =表格1[[#This Row],[加權後總分]]-表格1[[#This Row],[獎懲分數]] -> #DIV/0! | H34: =IF(表格1[[#This Row],[不包含獎懲總分]]>=90,"A", IF(表格1[[#This Row],[不包含獎懲總分]]>=80,"B", IF(表格1[[#This Row],[不包含獎懲總分]]>=70,"C", IF(表格1[[#This Row],[不包含獎懲總分]]>=60,"D","E")))) -> #DIV/0! | I34: =_xlfn.RANK.EQ(G34,$G$2:$G$146,0) -> #DIV/0! | J34: =IF( AND(M34<>"",N34<>"",O34<>""), M34*20% + N34*50% + O34*30%, IF( AND(M34<>"",N34="",O34=""), M34, IF( AND(M34="",N34<>"",O34=""), N34, IF( AND(M34="",N34="",O34<>""), O34, IF( AND(M34<>"",N34<>"",O34=""), M34/(20%+50%)*20% + N34/(20%+50%)*50%, IF( AND(M34<>"",N34="",O34<>""), M34/(20%+30%)*20% + O34/(20%+30%)*30%, IF( AND(M34="",N34<>"",O34<>""), N34/(50%+30%)*50% + O34/(50%+30%)*30%, "" ) ) ) ) ) ) + V34 ) -> #DIV/0! | K34: =IF(J34>=90,"A", IF(J34>=77,"B", IF(J34>=70,"C", IF(J34>=60,"D","E")))) -> #DIV/0! | L34: =_xlfn.RANK.EQ(J34,$J$2:$J$146,0) -> #DIV/0! | M34: =表格1_3[[#This Row],[部內平均]] -> #DIV/0! | O34: =表格1_3[[#This Row],[複評平均]] -> #DIV/0! | W34: 77.125 | X34: 32
A35: 移工 | B35: 2919 | C35: 及可 | D35: 組一組 | E35: 技術員 | F35: 陳怡珊 | G35: =表格1[[#This Row],[加權後總分]]-表格1[[#This Row],[獎懲分數]] -> #DIV/0! | H35: =IF(表格1[[#This Row],[不包含獎懲總分]]>=90,"A", IF(表格1[[#This Row],[不包含獎懲總分]]>=80,"B", IF(表格1[[#This Row],[不包含獎懲總分]]>=70,"C", IF(表格1[[#This Row],[不包含獎懲總分]]>=60,"D","E")))) -> #DIV/0! | I35: =_xlfn.RANK.EQ(G35,$G$2:$G$146,0) -> #DIV/0! | J35: =IF( AND(M35<>"",N35<>"",O35<>""), M35*20% + N35*50% + O35*30%, IF( AND(M35<>"",N35="",O35=""), M35, IF( AND(M35="",N35<>"",O35=""), N35, IF( AND(M35="",N35="",O35<>""), O35, IF( AND(M35<>"",N35<>"",O35=""), M35/(20%+50%)*20% + N35/(20%+50%)*50%, IF( AND(M35<>"",N35="",O35<>""), M35/(20%+30%)*20% + O35/(20%+30%)*30%, IF( AND(M35="",N35<>"",O35<>""), N35/(50%+30%)*50% + O35/(50%+30%)*30%, "" ) ) ) ) ) ) + V35 ) -> #DIV/0! | K35: =IF(J35>=90,"A", IF(J35>=77,"B", IF(J35>=70,"C", IF(J35>=60,"D","E")))) -> #DIV/0! | L35: =_xlfn.RANK.EQ(J35,$J$2:$J$146,0) -> #DIV/0! | M35: =表格1_3[[#This Row],[部內平均]] -> #DIV/0! | O35: =表格1_3[[#This Row],[複評平均]] -> #DIV/0! | W35: 77.061224 | X35: 33
A36: 移工 | B36: 3029 | C36: 吉沙達 | D36: 組一組 | E36: 技術員 | F36: 陳怡珊 | G36: =表格1[[#This Row],[加權後總分]]-表格1[[#This Row],[獎懲分數]] -> #DIV/0! | H36: =IF(表格1[[#This Row],[不包含獎懲總分]]>=90,"A", IF(表格1[[#This Row],[不包含獎懲總分]]>=80,"B", IF(表格1[[#This Row],[不包含獎懲總分]]>=70,"C", IF(表格1[[#This Row],[不包含獎懲總分]]>=60,"D","E")))) -> #DIV/0! | I36: =_xlfn.RANK.EQ(G36,$G$2:$G$146,0) -> #DIV/0! | J36: =IF( AND(M36<>"",N36<>"",O36<>""), M36*20% + N36*50% + O36*30%, IF( AND(M36<>"",N36="",O36=""), M36, IF( AND(M36="",N36<>"",O36=""), N36, IF( AND(M36="",N36="",O36<>""), O36, IF( AND(M36<>"",N36<>"",O36=""), M36/(20%+50%)*20% + N36/(20%+50%)*50%, IF( AND(M36<>"",N36="",O36<>""), M36/(20%+30%)*20% + O36/(20%+30%)*30%, IF( AND(M36="",N36<>"",O36<>""), N36/(50%+30%)*50% + O36/(50%+30%)*30%, "" ) ) ) ) ) ) + V36 ) -> #DIV/0! | K36: =IF(J36>=90,"A", IF(J36>=77,"B", IF(J36>=70,"C", IF(J36>=60,"D","E")))) -> #DIV/0! | L36: =_xlfn.RANK.EQ(J36,$J$2:$J$146,0) -> #DIV/0! | M36: =表格1_3[[#This Row],[部內平均]] -> #DIV/0! | O36: =表格1_3[[#This Row],[複評平均]] -> #DIV/0! | W36: 77 | X36: 34
B37: 2216 | C37: 陳怡珊 | D37: 組一組 | E37: 副組長 | F37: 楊玉鳳 | G37: =表格1[[#This Row],[加權後總分]]-表格1[[#This Row],[獎懲分數]] -> #DIV/0! | H37: =IF(表格1[[#This Row],[不包含獎懲總分]]>=90,"A", IF(表格1[[#This Row],[不包含獎懲總分]]>=80,"B", IF(表格1[[#This Row],[不包含獎懲總分]]>=70,"C", IF(表格1[[#This Row],[不包含獎懲總分]]>=60,"D","E")))) -> #DIV/0! | I37: =_xlfn.RANK.EQ(G37,$G$2:$G$146,0) -> #DIV/0! | J37: =IF( AND(M37<>"",N37<>"",O37<>""), M37*20% + N37*50% + O37*30%, IF( AND(M37<>"",N37="",O37=""), M37, IF( AND(M37="",N37<>"",O37=""), N37, IF( AND(M37="",N37="",O37<>""), O37, IF( AND(M37<>"",N37<>"",O37=""), M37/(20%+50%)*20% + N37/(20%+50%)*50%, IF( AND(M37<>"",N37="",O37<>""), M37/(20%+30%)*20% + O37/(20%+30%)*30%, IF( AND(M37="",N37<>"",O37<>""), N37/(50%+30%)*50% + O37/(50%+30%)*30%, "" ) ) ) ) ) ) + V37 ) -> #DIV/0! | K37: =IF(J37>=90,"A", IF(J37>=77,"B", IF(J37>=70,"C", IF(J37>=60,"D","E")))) -> #DIV/0! | L37: =_xlfn.RANK.EQ(J37,$J$2:$J$146,0) -> #DIV/0! | M37: =表格1_3[[#This Row],[部內平均]] -> #DIV/0! | N37: =表格1_3[[#This Row],[共評平均]] -> #DIV/0! | O37: =表格1_3[[#This Row],[複評平均]] -> #DIV/0! | W37: 77 | X37: 35
A38: 現場 | B38: 1547 | C38: 鄭萍 | D38: 沖床組 | E38: 技術員 | F38: 覃麗嬋 | G38: =表格1[[#This Row],[加權後總分]]-表格1[[#This Row],[獎懲分數]] -> #DIV/0! | H38: =IF(表格1[[#This Row],[不包含獎懲總分]]>=90,"A", IF(表格1[[#This Row],[不包含獎懲總分]]>=80,"B", IF(表格1[[#This Row],[不包含獎懲總分]]>=70,"C", IF(表格1[[#This Row],[不包含獎懲總分]]>=60,"D","E")))) -> #DIV/0! | I38: =_xlfn.RANK.EQ(G38,$G$2:$G$146,0) -> #DIV/0! | J38: =IF( AND(M38<>"",N38<>"",O38<>""), M38*20% + N38*50% + O38*30%, IF( AND(M38<>"",N38="",O38=""), M38, IF( AND(M38="",N38<>"",O38=""), N38, IF( AND(M38="",N38="",O38<>""), O38, IF( AND(M38<>"",N38<>"",O38=""), M38/(20%+50%)*20% + N38/(20%+50%)*50%, IF( AND(M38<>"",N38="",O38<>""), M38/(20%+30%)*20% + O38/(20%+30%)*30%, IF( AND(M38="",N38<>"",O38<>""), N38/(50%+30%)*50% + O38/(50%+30%)*30%, "" ) ) ) ) ) ) + V38 ) -> #DIV/0! | K38: =IF(J38>=90,"A", IF(J38>=77,"B", IF(J38>=70,"C", IF(J38>=60,"D","E")))) -> #DIV/0! | L38: =_xlfn.RANK.EQ(J38,$J$2:$J$146,0) -> #DIV/0! | M38: =表格1_3[[#This Row],[部內平均]] -> #DIV/0! | O38: =表格1_3[[#This Row],[複評平均]] -> #DIV/0! | W38: 76.959184 | X38: 36
B39: 2097 | C39: 覃麗嬋 | D39: 沖床組 | E39: 副組長 | F39: 周清家 | G39: =表格1[[#This Row],[加權後總分]]-表格1[[#This Row],[獎懲分數]] -> #DIV/0! | H39: =IF(表格1[[#This Row],[不包含獎懲總分]]>=90,"A", IF(表格1[[#This Row],[不包含獎懲總分]]>=80,"B", IF(表格1[[#This Row],[不包含獎懲總分]]>=70,"C", IF(表格1[[#This Row],[不包含獎懲總分]]>=60,"D","E")))) -> #DIV/0! | I39: =_xlfn.RANK.EQ(G39,$G$2:$G$146,0) -> #DIV/0! | J39: =IF( AND(M39<>"",N39<>"",O39<>""), M39*20% + N39*50% + O39*30%, IF( AND(M39<>"",N39="",O39=""), M39, IF( AND(M39="",N39<>"",O39=""), N39, IF( AND(M39="",N39="",O39<>""), O39, IF( AND(M39<>"",N39<>"",O39=""), M39/(20%+50%)*20% + N39/(20%+50%)*50%, IF( AND(M39<>"",N39="",O39<>""), M39/(20%+30%)*20% + O39/(20%+30%)*30%, IF( AND(M39="",N39<>"",O39<>""), N39/(50%+30%)*50% + O39/(50%+30%)*30%, "" ) ) ) ) ) ) + V39 ) -> #DIV/0! | K39: =IF(J39>=90,"A", IF(J39>=77,"B", IF(J39>=70,"C", IF(J39>=60,"D","E")))) -> #DIV/0! | L39: =_xlfn.RANK.EQ(J39,$J$2:$J$146,0) -> #DIV/0! | M39: =表格1_3[[#This Row],[部內平均]] -> #DIV/0! | N39: =表格1_3[[#This Row],[共評平均]] -> #DIV/0! | O39: =表格1_3[[#This Row],[複評平均]] -> #DIV/0! | W39: 76.816667 | X39: 37
